Workbook

Sheet Candle
A1: Candle
A3: Weigh in | B3: grams
A4: Currency | B4: $
A6: Jar
A7: Water weight | C7: =IF('Candle'!$B$3="grams","g","oz") | D7: jar filled to your line
A8: Wax factor | B8: 0.86 | D8: planning assumption — waxes vary
A9: Fill weight | B9: =IF(OR($B$7="",$B$8=""),"",$B$7*$B$8) | C9: =IF('Candle'!$B$3="grams","g","oz")
A11: Fragrance
A12: Measured as | B12: Load (% of wax) | D12: load = % of wax · content = % of wax + fragrance
A13: Fragrance %
A14: Wax maximum | D14: optional — from your wax spec sheet
B15: =IF(OR($B$9="",$B$13="",$B$13>=1),"",IF(AND($B$14<>"",$B$13>$B$14),"Above the maximum you entered ("&TEXT($B$14,"0.0%")&"). Your wax may not hold it.",""))
A17: Per candle
A18: Wax | B18: =IF(OR($B$9="",$B$13="",$B$13>=1),"",IF($B$12="Load (% of wax)",$B$9/(1+$B$13),$B$9*(1-$B$13))) | C18: =IF('Candle'!$B$3="grams","g","oz")
A19: Fragrance oil | B19: =IF(OR($B$9="",$B$13="",$B$13>=1),"",IF($B$12="Load (% of wax)",$B$9*$B$13/(1+$B$13),$B$9*$B$13)) | C19: =IF('Candle'!$B$3="grams","g","oz")
A20: Fill weight | B20: =IF($B$9="","",$B$9) | C20: =IF('Candle'!$B$3="grams","g","oz")
A21: Load | B21: =IF(OR($B$9="",$B$13="",$B$13>=1),"",IF($B$12="Load (% of wax)",$B$13,$B$13/(1-$B$13))) | D21: % of wax
A22: Content | B22: =IF(OR($B$9="",$B$13="",$B$13>=1),"",IF($B$12="Load (% of wax)",$B$13/(1+$B$13),$B$13)) | D22: % of wax + fragrance
A24: Batch
A25: Candles
A26: Pitcher loss | B26: 0 | D26: extra wax left in the pitcher
A27: Wax | B27: =IF(OR($B$18="",$B$25=""),"",$B$18*$B$25*(1+$B$26)) | C27: =IF('Candle'!$B$3="grams","g","oz")
A28: Fragrance oil | B28: =IF(OR($B$19="",$B$25=""),"",$B$19*$B$25*(1+$B$26)) | C28: =IF('Candle'!$B$3="grams","g","oz")

Sheet Costs & Price
A1: Costs & Price
A3: Materials
B4: Price paid | C4: Quantity | D4: Unit
A5: Wax | D5: kg
A6: Fragrance oil | D6: g
A7: Wax per unit | B7: =IF(OR($B$5="",$C$5="",$C$5=0),"",$B$5/($C$5*IF($D$5="g",1,IF($D$5="kg",1000,IF($D$5="oz",28.349523125,453.59237)))/IF('Candle'!$B$3="grams",1,28.349523125)))
A8: Fragrance per unit | B8: =IF(OR($B$6="",$C$6="",$C$6=0),"",$B$6/($C$6*IF($D$6="g",1,IF($D$6="kg",1000,IF($D$6="oz",28.349523125,453.59237)))/IF('Candle'!$B$3="grams",1,28.349523125)))
A10: Parts per candle
A11: Vessel
A12: Wick
A13: Lid
A14: Label
A15: Packaging
A16: Other
A18: Labour
A19: Include | B19: No | D19: optional
A20: Minutes per candle
A21: Hourly rate
A23: Overhead
A24: Include | B24: No | D24: optional — rent, insurance, subscriptions
A25: Monthly cost
A26: Candles per month
B27: =IF(AND($B$24="Yes",OR($B$26="",$B$26=0)),"Enter candles per month, or set Include to No.","")
A29: Cost per candle
A30: Wax + fragrance | B30: =IF(OR('Candle'!$B$27="",$B$7="",$B$8="",'Candle'!$B$25=""),"",('Candle'!$B$27*$B$7+'Candle'!$B$28*$B$8)/'Candle'!$B$25)
A31: Parts | B31: =SUM($B$11:$B$16)
A32: Labour | B32: =IF($B$19<>"Yes",0,IF(OR($B$20="",$B$21=""),"",$B$20/60*$B$21))
A33: Overhead | B33: =IF($B$24<>"Yes",0,IF(OR($B$25="",$B$26="",$B$26=0),"",$B$25/$B$26))
A34: Total | B34: =IF(OR($B$30="",$B$32="",$B$33=""),"",$B$30+$B$31+$B$32+$B$33)
A36: Selling fees
A37: Channel | D37: look up your marketplace's current fees
A38: Selling fee
A39: Processing
A40: Other %
A41: Fixed per order
A42: Charged on | B42: Item only | D42: item only, or item + shipping
A43: Shipping charged
A44: Shipping cost
A46: Price
A47: Target margin | D47: share of price, not markup on cost
...

Sheet Reference
A1: Reference
A3: Wick sizing
A4: Not calculated here. | C4: Depends on wax, fragrance load, dye and jar shape. Found by burn testing.
A5: Use | C5: The printable Burn Test Log supplied with this sheet.
A7: Starting assumptions
A8: Assumption | B8: Starts at | C8: Change it on
A9: Wax factor | B9: 0.86 | C9: Candle · wax is about 86% the density of water; waxes vary
A10: Pitcher loss | B10: 0% | C10: Candle · depends on your pitcher and pour
A11: Wholesale multiplier | B11: 2.00 | C11: Costs & Price
A12: Selling fees | B12: blank | C12: Costs & Price · enter your own current rates
A13: Labour, overhead | B13: off | C13: Costs & Price
A15: Load and content
A16: Load | C16: Fragrance as a % of the wax alone.
A17: Content | C17: Fragrance as a % of wax + fragrance.
A18: Example | C18: 20 g fragrance in 200 g wax = 10% load, 9.09% content.
A19: Reference point | C19: 1 oz fragrance per 1 lb wax = 6.25% load.
A21: Margin and markup
A22: Margin | C22: Profit ÷ price.
A23: Markup | C23: Profit ÷ cost.
A24: Watch out | C24: Adding 40% to cost gives a 29% margin, not 40%.
A26: Fee boxes
A27: Selling fee | C27: Marketplace commission.
A28: Processing | C28: Payment provider.
A29: Other % | C29: Advertising or similar.
A30: Fixed per order | C30: Flat amount, not a percentage.
A31: Charged on | C31: Some charge on item + shipping, others item only.
A33: Cell colours
C34: Type here
C35: Calculated
C36: Assumption you can change
