Workbook

Sheet Start Here
A1: Candle Batch & Pricing Calculator
A2: Work out exactly how much wax and fragrance to melt, what each candle costs you, and what to charge.
A4: First, two quick settings
A5: I weigh things in | B5: grams | D5: Everything below switches to match.
A6: Currency symbol | B6: $ | D6: Just for labels. Nothing is converted.
A7: Short unit label | B7: =IF($B$5="grams","g","oz") | D7: These two lines do the unit switching. Leave them as they are.
A8: Grams in one of your units | B8: =IF($B$5="grams",1,28.349523125)
A10: The one thing that trips people up
A11: Fragrance load and fragrance content are different numbers.
A12: Fragrance LOAD is a percentage of the wax on its own.
A13: Fragrance CONTENT is a percentage of the wax and fragrance added together.
A14: Put 20 g of fragrance into 200 g of wax and you have a 10% load — but 9.09% content (20 out of 220 g).
A15: Same candle. Two numbers. Use whichever your recipe or your wax sheet uses — this sheet always shows you both.
A17: How to measure your jar
A18: 1. Put your empty jar on the scale and zero it.
A19: 2. Fill it with water to the height you want the wax to reach, leaving room for the lid.
A20: 3. Write that water weight down. That is the number this sheet starts from.
A22: Colour key
A23: Type in these
... A25: Starting assumptions you can change

Sheet Your Candle
A1: Your Candle
A3: Your jar
A4: Water weight of your jar, filled to your line | B4: 300 | C4: ='Start Here'!$B$7
A5: Water-to-wax factor | B5: 0.86 | D5: A planning assumption, not a physical constant. Waxes differ — measure your own and change this.
A6: Fill weight — how much wax + fragrance fits | B6: =IF(OR($B$4="",$B$5=""),"",$B$4*$B$5) | C6: ='Start Here'!$B$7
A8: Your fragrance
A9: How you measure fragrance | B9: Fragrance load (% of wax) | D9: This sheet shows you both numbers either way.
A10: Fragrance percentage | B10: 0.12
A11: Maximum your wax can hold | B11: 0.1 | D11: Optional. From your wax's spec sheet — enter it the same way you are measuring above.
B12: =IF(OR($B$6="",$B$10="",$B$10>=1),"",IF(AND($B$11<>"",$B$10>$B$11),"Above the maximum you entered for this wax ("&TEXT($B$11,"0.0%")&"). Your wax may not hold it.",""))
A14: One candle
A15: Wax | B15: =IF(OR($B$6="",$B$10="",$B$10>=1),"",IF($B$9="Fragrance load (% of wax)",$B$6/(1+$B$10),$B$6*(1-$B$10))) | C15: ='Start Here'!$B$7
A16: Fragrance oil | B16: =IF(OR($B$6="",$B$10="",$B$10>=1),"",IF($B$9="Fragrance load (% of wax)",$B$6*$B$10/(1+$B$10),$B$6*$B$10)) | C16: ='Start Here'!$B$7
A17: Total fill weight | B17: =IF($B$6="","",$B$6) | C17: ='Start Here'!$B$7
A18: Fragrance load (% of wax) | B18: =IF(OR($B$6="",$B$10="",$B$10>=1),"",IF($B$9="Fragrance load (% of wax)",$B$10,$B$10/(1-$B$10))) | D18: Both are shown on purpose. They describe the same candle.
A19: Fragrance content (% of wax + fragrance) | B19: =IF(OR($B$6="",$B$10="",$B$10>=1),"",IF($B$9="Fragrance load (% of wax)",$B$10/(1+$B$10),$B$10))
A21: Your batch
A22: How many candles in this batch | B22: 12
A23: Extra wax for what stays in the pitcher | B23: 0 | D23: Starts at 0%. Raise it if you know how much you normally lose.
A24: Wax for the whole batch | B24: =IF(OR($B$15="",$B$22=""),"",$B$15*$B$22*(1+$B$23)) | C24: ='Start Here'!$B$7
A25: Fragrance oil for the whole batch | B25: =IF(OR($B$16="",$B$22=""),"",$B$16*$B$22*(1+$B$23)) | C25: ='Start Here'!$B$7

Sheet Costs & Price
A1: Costs & Price
A3: What your materials cost
B4: What you paid | C4: How much that bought | D4: Sold in
A5: Wax | B5: 30 | C5: 5 | D5: kg
A6: Fragrance oil | B6: 18 | C6: 500 | D6: g
A7: Cost of wax, per unit you weigh in | B7: =IF(OR($B$5="",$C$5="",$C$5=0),"",$B$5/($C$5*IF($D$5="g",1,IF($D$5="kg",1000,IF($D$5="oz",28.349523125,453.59237)))/'Start Here'!$B$8))
A8: Cost of fragrance oil, per unit you weigh in | B8: =IF(OR($B$6="",$C$6="",$C$6=0),"",$B$6/($C$6*IF($D$6="g",1,IF($D$6="kg",1000,IF($D$6="oz",28.349523125,453.59237)))/'Start Here'!$B$8))
A10: Parts for one candle
A11: Vessel | B11: 1.8
A12: Wick | B12: 0.12
A13: Lid | B13: 0.6
A14: Label | B14: 0.15
A15: Box or packaging | B15: 0.45
A16: Anything else | B16: 0
A18: Your time (optional)
A19: Pay myself for my time | B19: No | D19: Your time is a real cost. If you skip this, your price only covers materials.
A20: Minutes to make one candle
A21: What I pay myself per hour
A23: Your running costs (optional)
A24: Include my monthly running costs | B24: No | D24: Rent, insurance, subscriptions — costs you pay whether or not you make a candle this month.
A25: My monthly running costs
A26: Candles I make in a month
B27: =IF(AND($B$24="Yes",OR($B$26="",$B$26=0)),"Enter how many candles you make in a month, or switch running costs off.","")
A29: What one candle costs you
A30: Wax + fragrance | B30: =IF(OR('Your Candle'!$B$24="",$B$7="",$B$8="",'Your Candle'!$B$22=""),"",('Your Candle'!$B$24*$B$7+'Your Candle'!$B$25*$B$8)/'Your Candle'!$B$22)
A31: Other parts | B31: =SUM($B$11:$B$16)
A32: Your time | B32: =IF($B$19<>"Yes",0,IF(OR($B$20="",$B$21=""),"",$B$20/60*$B$21))
A33: Share of running costs | B33: =IF($B$24<>"Yes",0,IF(OR($B$25="",$B$26="",$B$26=0),"",$B$25/$B$26))
A34: TOTAL cost per candle | B34: =IF(OR($B$30="",$B$32="",$B$33=""),"",$B$30+$B$31+$B$32+$B$33)
A36: Where you're selling
A37: Where am I selling this | D37: Fees change. Look up your marketplace's current fees and type them in — this sheet does not guess them for you.
A38: Selling fee %
A39: Payment processing %
A40: Any other % fee
A41: Fixed fee per order
A42: Percentage fees apply to | B42: Item price only
A43: Shipping I charge the buyer | B43: 0
A44: What shipping actually costs me | B44: 0
A46: Your price
A47: Profit margin I want | B47: 0.4 | D47: As a share of the price you charge.
...

Sheet Reference
A1: Reference
A3: What this sheet does not do
A4: This workbook does not choose your wick.
A5: Wick size cannot be calculated. It depends on your wax, fragrance load, dye, and the diameter and shape of your vessel — the only way to know is to burn a test candle and watch the melt pool.
A6: Use the burn test log that came with this sheet for that.
A8: Starting assumptions — all of them, and where to change them
A9: Assumption | B9: Starts at | C9: Why, and where to change it
A10: Water-to-wax factor | B10: 0.86 | C10: Wax is lighter than water — around 86% of its density. A planning assumption, not a constant. Waxes differ. Change it on Your Candle.
A11: Extra wax for the pitcher | B11: 0% | C11: Starts at zero, because how much you lose depends on your pitcher and how you pour. Change it on Your Candle.
A12: Wholesale multiplier | B12: 2.00 | C12: A common starting point is twice what the candle costs you. Change it on Costs & Price.
A13: Selling fees | B13: blank | C13: Left empty on purpose. Fees change, and they differ by marketplace and country. Look up yours and type them in on Costs & Price.
A14: Your time and running costs | B14: off | C14: Both optional. Switch them on when you want your price to cover them.
A17: Fragrance load and fragrance content
A18: Fragrance load | C18: The fragrance as a percentage of the wax on its own.
A19: Fragrance content | C19: The fragrance as a percentage of the wax and fragrance added together.
A20: The worked example | C20: 20 g of fragrance in 200 g of wax is a 10% load, and 9.09% content (20 out of 220 g). Same candle.
A21: A handy reference point | C21: 1 oz of fragrance per 1 lb of wax is a 6.25% load.
A23: Selling fees — what the boxes mean
A24: Selling fee % | C24: What the marketplace charges you for making the sale.
A25: Payment processing % | C25: What the payment provider charges for taking the money.
A26: Any other % fee | C26: Anything else charged as a percentage — advertising, for example.
A27: Fixed fee per order | C27: A flat amount per order rather than a percentage.
A28: Percentage fees apply to | C28: Some places charge their percentage on the item price plus the shipping you charge. Others only on the item price. Check yours.
A31: Margin and markup
A32: Margin | C32: Your profit as a share of the price you charge.
A33: Markup | C33: Your profit as a share of what the candle cost you.
A34: Why it matters | C34: Adding 40% to your cost does not give you a 40% margin. This sheet works out the price that actually gives you the margin you asked for, after fees.
