Workbook

Sheet Start Here
A1: Craft Fair & Farmers Market Profit Tracker — Start Here
A2: Use your own sales, costs and time to compare markets before paying the next booth fee.
A4: USE THE WORKBOOK IN THIS ORDER
A6: 1 | B6: 1 — TARGETS: Enter the minimum profit margin, profit per market hour and stock sold % you want to use. These are your goals—not recommendations.
A7: 2 | B7: 2 — MARKET DAYS: Enter one row per event: date, market, booth fee, travel, hours worked at the market and the event total sales you want to keep for reference.
A8: 3 | B8: 3 — PRODUCT SALES: Add one row per product batch sold there. These product-sales rows drive the calculated sales and profit results. Enter units, sales, product costs, product work hours and the value you assign to one hour of that work.
A9: 4 | B9: 4 — MARKET COMPARISON: Compare up to five market names. MEETS TARGETS means all three of your entered goals were reached; REVIEW means at least one was not.
A11: COLOR KEY
A13: TYPE HERE | D13: CALCULATED | G13: CHECK / ALERT
A16: HOW THE NUMBERS WORK
A18: Hours Worked on Market Days means time spent working the event and is used for the market-level Profit per Market Hour result. Product Work Hours on Product Sales means time spent making or preparing that product batch; Product Work Hours × Value of Your Time / Hour is included in the entered costs. Booth fee and travel are divided evenly across READY product rows for that event.
A22: IMPORTANT BEFORE YOU USE THE RESULTS
A24: Profit After Entered Costs means sales minus entered ingredients, packaging, product work hours × your entered time value, and that row's equal share of booth fee + travel. It is not accounting profit, take-home pay or a tax result, and it does not include every possible business expense. Capacity: 50 market-day rows, 100 product-sales rows and 5 market names in Market Comparison.

Sheet Targets
A1: Decision Targets
A2: Set the three goals used for MEETS TARGETS. These are your choices—not suggested business targets.
A4: Your Target | B4: Value | C4: What This Means | D4: Input Check / What to Fix
A5: Minimum Profit Margin | B5: 0.3 | C5: Profit After Entered Costs ÷ Sales. Enter 0% to under 100%. | D5: =IFERROR(IF(NOT(ISNUMBER(B5)),"ENTER 0% TO UNDER 100%",IF(OR(B5<0,B5>=1),"ENTER 0% TO UNDER 100%","READY")),"FIX THIS TARGET") -> READY
A6: Minimum Profit per Market Hour | B6: 20 | C6: Minimum Profit After Entered Costs you want for each hour worked at the market. | D6: =IFERROR(IF(NOT(ISNUMBER(B6)),"ENTER 0 OR MORE",IF(B6<0,"ENTER 0 OR MORE","READY")),"FIX THIS TARGET") -> READY
A7: Minimum Stock Sold % | B7: 0.7 | C7: Units sold ÷ units brought. Enter 0% to 100%. | D7: =IFERROR(IF(NOT(ISNUMBER(B7)),"ENTER 0% TO 100%",IF(OR(B7<0,B7>1),"ENTER 0% TO 100%","READY")),"FIX THIS TARGET") -> READY

Sheet Market Days
A1: Market Days
A2: Enter one row per event. Hours Worked at Market means time spent working that event—not time spent making products beforehand. Event Total Sales is kept for reference; calculated results use the product sales entered on Product Sales.
A3: SAMPLE DATA — rows 5 to 7 below are examples. Delete them before entering your own market days.
A4: Market Date | B4: Market Name | C4: Booth Fee | D4: Travel Cost | E4: Hours Worked at Market | F4: Event Total Sales (Reference) | G4: Transactions (Optional) | H4: Notes (Optional) | I4: Input Check / What to Fix
A5: 46250 | B5: Saturday Market | C5: 75 | D5: 24 | E5: 7 | F5: 680 | G5: 42 | H5: Sample — replace | I5: =IF(COUNTA(A5:H5)=0,"",IFERROR(IF(A5="","ENTER MARKET DATE",IF(NOT(ISNUMBER(A5)),"ENTER A VALID DATE",IF(B5="","ENTER MARKET NAME",IF(NOT(ISTEXT(B5)),"ENTER MARKET NAME AS TEXT",IF(COUNTIFS($A$5:$A$54,A5,$B$5:$B$54,B5)>1,"REMOVE DUPLICATE MARKET DAY",IF(OR(NOT(ISNUMBER(C5)),C5<0),"ENTER BOOTH FEE AS 0 OR MORE",IF(OR(NOT(ISNUMBER(D5)),D5<0),"ENTER TRAVEL COST AS 0 OR MORE",IF(OR(NOT(ISNUMBER(E5)),E5<=0),"ENTER MARKET HOURS ABOVE 0",IF(OR(NOT(ISNUMBER(F5)),F5<0),"ENTER SALES AS 0 OR MORE",IF(AND(G5<>"",OR(NOT(ISNUMBER(G5)),G5<0,G5<>INT(G5))),"ENTER TRANSACTIONS AS A WHOLE NUMBER","READY")))))))))),"FIX INVALID MARKET ENTRY")) -> READY
A6: 46257 | B6: Riverside Pop-Up | C6: 45 | D6: 18 | E6: 5 | F6: 510 | G6: 31 | H6: Sample — replace | I6: =IF(COUNTA(A6:H6)=0,"",IFERROR(IF(A6="","ENTER MARKET DATE",IF(NOT(ISNUMBER(A6)),"ENTER A VALID DATE",IF(B6="","ENTER MARKET NAME",IF(NOT(ISTEXT(B6)),"ENTER MARKET NAME AS TEXT",IF(COUNTIFS($A$5:$A$54,A6,$B$5:$B$54,B6)>1,"REMOVE DUPLICATE MARKET DAY",IF(OR(NOT(ISNUMBER(C6)),C6<0),"ENTER BOOTH FEE AS 0 OR MORE",IF(OR(NOT(ISNUMBER(D6)),D6<0),"ENTER TRAVEL COST AS 0 OR MORE",IF(OR(NOT(ISNUMBER(E6)),E6<=0),"ENTER MARKET HOURS ABOVE 0",IF(OR(NOT(ISNUMBER(F6)),F6<0),"ENTER SALES AS 0 OR MORE",IF(AND(G6<>"",OR(NOT(ISNUMBER(G6)),G6<0,G6<>INT(G6))),"ENTER TRANSACTIONS AS A WHOLE NUMBER","READY")))))))))),"FIX INVALID MARKET ENTRY")) -> READY
A7: 46264 | B7: Night Bazaar | C7: 110 | D7: 30 | E7: 8 | F7: 740 | G7: 46 | H7: Sample — replace | I7: =IF(COUNTA(A7:H7)=0,"",IFERROR(IF(A7="","ENTER MARKET DATE",IF(NOT(ISNUMBER(A7)),"ENTER A VALID DATE",IF(B7="","ENTER MARKET NAME",IF(NOT(ISTEXT(B7)),"ENTER MARKET NAME AS TEXT",IF(COUNTIFS($A$5:$A$54,A7,$B$5:$B$54,B7)>1,"REMOVE DUPLICATE MARKET DAY",IF(OR(NOT(ISNUMBER(C7)),C7<0),"ENTER BOOTH FEE AS 0 OR MORE",IF(OR(NOT(ISNUMBER(D7)),D7<0),"ENTER TRAVEL COST AS 0 OR MORE",IF(OR(NOT(ISNUMBER(E7)),E7<=0),"ENTER MARKET HOURS ABOVE 0",IF(OR(NOT(ISNUMBER(F7)),F7<0),"ENTER SALES AS 0 OR MORE",IF(AND(G7<>"",OR(NOT(ISNUMBER(G7)),G7<0,G7<>INT(G7))),"ENTER TRANSACTIONS AS A WHOLE NUMBER","READY")))))))))),"FIX INVALID MARKET ENTRY")) -> READY
I8: =IF(COUNTA(A8:H8)=0,"",IFERROR(IF(A8="","ENTER MARKET DATE",IF(NOT(ISNUMBER(A8)),"ENTER A VALID DATE",IF(B8="","ENTER MARKET NAME",IF(NOT(ISTEXT(B8)),"ENTER MARKET NAME AS TEXT",IF(COUNTIFS($A$5:$A$54,A8,$B$5:$B$54,B8)>1,"REMOVE DUPLICATE MARKET DAY",IF(OR(NOT(ISNUMBER(C8)),C8<0),"ENTER BOOTH FEE AS 0 OR MORE",IF(OR(NOT(ISNUMBER(D8)),D8<0),"ENTER TRAVEL COST AS 0 OR MORE",IF(OR(NOT(ISNUMBER(E8)),E8<=0),"ENTER MARKET HOURS ABOVE 0",IF(OR(NOT(ISNUMBER(F8)),F8<0),"ENTER SALES AS 0 OR MORE",IF(AND(G8<>"",OR(NOT(ISNUMBER(G8)),G8<0,G8<>INT(G8))),"ENTER TRANSACTIONS AS A WHOLE NUMBER","READY")))))))))),"FIX INVALID MARKET ENTRY"))
I9: =IF(COUNTA(A9:H9)=0,"",IFERROR(IF(A9="","ENTER MARKET DATE",IF(NOT(ISNUMBER(A9)),"ENTER A VALID DATE",IF(B9="","ENTER MARKET NAME",IF(NOT(ISTEXT(B9)),"ENTER MARKET NAME AS TEXT",IF(COUNTIFS($A$5:$A$54,A9,$B$5:$B$54,B9)>1,"REMOVE DUPLICATE MARKET DAY",IF(OR(NOT(ISNUMBER(C9)),C9<0),"ENTER BOOTH FEE AS 0 OR MORE",IF(OR(NOT(ISNUMBER(D9)),D9<0),"ENTER TRAVEL COST AS 0 OR MORE",IF(OR(NOT(ISNUMBER(E9)),E9<=0),"ENTER MARKET HOURS ABOVE 0",IF(OR(NOT(ISNUMBER(F9)),F9<0),"ENTER SALES AS 0 OR MORE",IF(AND(G9<>"",OR(NOT(ISNUMBER(G9)),G9<0,G9<>INT(G9))),"ENTER TRANSACTIONS AS A WHOLE NUMBER","READY")))))))))),"FIX INVALID MARKET ENTRY"))
I10: =IF(COUNTA(A10:H10)=0,"",IFERROR(IF(A10="","ENTER MARKET DATE",IF(NOT(ISNUMBER(A10)),"ENTER A VALID DATE",IF(B10="","ENTER MARKET NAME",IF(NOT(ISTEXT(B10)),"ENTER MARKET NAME AS TEXT",IF(COUNTIFS($A$5:$A$54,A10,$B$5:$B$54,B10)>1,"REMOVE DUPLICATE MARKET DAY",IF(OR(NOT(ISNUMBER(C10)),C10<0),"ENTER BOOTH FEE AS 0 OR MORE",IF(OR(NOT(ISNUMBER(D10)),D10<0),"ENTER TRAVEL COST AS 0 OR MORE",IF(OR(NOT(ISNUMBER(E10)),E10<=0),"ENTER MARKET HOURS ABOVE 0",IF(OR(NOT(ISNUMBER(F10)),F10<0),"ENTER SALES AS 0 OR MORE",IF(AND(G10<>"",OR(NOT(ISNUMBER(G10)),G10<0,G10<>INT(G10))),"ENTER TRANSACTIONS AS A WHOLE NUMBER","READY")))))))))),"FIX INVALID MARKET ENTRY"))
I11: =IF(COUNTA(A11:H11)=0,"",IFERROR(IF(A11="","ENTER MARKET DATE",IF(NOT(ISNUMBER(A11)),"ENTER A VALID DATE",IF(B11="","ENTER MARKET NAME",IF(NOT(ISTEXT(B11)),"ENTER MARKET NAME AS TEXT",IF(COUNTIFS($A$5:$A$54,A11,$B$5:$B$54,B11)>1,"REMOVE DUPLICATE MARKET DAY",IF(OR(NOT(ISNUMBER(C11)),C11<0),"ENTER BOOTH FEE AS 0 OR MORE",IF(OR(NOT(ISNUMBER(D11)),D11<0),"ENTER TRAVEL COST AS 0 OR MORE",IF(OR(NOT(ISNUMBER(E11)),E11<=0),"ENTER MARKET HOURS ABOVE 0",IF(OR(NOT(ISNUMBER(F11)),F11<0),"ENTER SALES AS 0 OR MORE",IF(AND(G11<>"",OR(NOT(ISNUMBER(G11)),G11<0,G11<>INT(G11))),"ENTER TRANSACTIONS AS A WHOLE NUMBER","READY")))))))))),"FIX INVALID MARKET ENTRY"))
I12: =IF(COUNTA(A12:H12)=0,"",IFERROR(IF(A12="","ENTER MARKET DATE",IF(NOT(ISNUMBER(A12)),"ENTER A VALID DATE",IF(B12="","ENTER MARKET NAME",IF(NOT(ISTEXT(B12)),"ENTER MARKET NAME AS TEXT",IF(COUNTIFS($A$5:$A$54,A12,$B$5:$B$54,B12)>1,"REMOVE DUPLICATE MARKET DAY",IF(OR(NOT(ISNUMBER(C12)),C12<0),"ENTER BOOTH FEE AS 0 OR MORE",IF(OR(NOT(ISNUMBER(D12)),D12<0),"ENTER TRAVEL COST AS 0 OR MORE",IF(OR(NOT(ISNUMBER(E12)),E12<=0),"ENTER MARKET HOURS ABOVE 0",IF(OR(NOT(ISNUMBER(F12)),F12<0),"ENTER SALES AS 0 OR MORE",IF(AND(G12<>"",OR(NOT(ISNUMBER(G12)),G12<0,G12<>INT(G12))),"ENTER TRANSACTIONS AS A WHOLE NUMBER","READY")))))))))),"FIX INVALID MARKET ENTRY"))
I13: =IF(COUNTA(A13:H13)=0,"",IFERROR(IF(A13="","ENTER MARKET DATE",IF(NOT(ISNUMBER(A13)),"ENTER A VALID DATE",IF(B13="","ENTER MARKET NAME",IF(NOT(ISTEXT(B13)),"ENTER MARKET NAME AS TEXT",IF(COUNTIFS($A$5:$A$54,A13,$B$5:$B$54,B13)>1,"REMOVE DUPLICATE MARKET DAY",IF(OR(NOT(ISNUMBER(C13)),C13<0),"ENTER BOOTH FEE AS 0 OR MORE",IF(OR(NOT(ISNUMBER(D13)),D13<0),"ENTER TRAVEL COST AS 0 OR MORE",IF(OR(NOT(ISNUMBER(E13)),E13<=0),"ENTER MARKET HOURS ABOVE 0",IF(OR(NOT(ISNUMBER(F13)),F13<0),"ENTER SALES AS 0 OR MORE",IF(AND(G13<>"",OR(NOT(ISNUMBER(G13)),G13<0,G13<>INT(G13))),"ENTER TRANSACTIONS AS A WHOLE NUMBER","READY")))))))))),"FIX INVALID MARKET ENTRY"))
I14: =IF(COUNTA(A14:H14)=0,"",IFERROR(IF(A14="","ENTER MARKET DATE",IF(NOT(ISNUMBER(A14)),"ENTER A VALID DATE",IF(B14="","ENTER MARKET NAME",IF(NOT(ISTEXT(B14)),"ENTER MARKET NAME AS TEXT",IF(COUNTIFS($A$5:$A$54,A14,$B$5:$B$54,B14)>1,"REMOVE DUPLICATE MARKET DAY",IF(OR(NOT(ISNUMBER(C14)),C14<0),"ENTER BOOTH FEE AS 0 OR MORE",IF(OR(NOT(ISNUMBER(D14)),D14<0),"ENTER TRAVEL COST AS 0 OR MORE",IF(OR(NOT(ISNUMBER(E14)),E14<=0),"ENTER MARKET HOURS ABOVE 0",IF(OR(NOT(ISNUMBER(F14)),F14<0),"ENTER SALES AS 0 OR MORE",IF(AND(G14<>"",OR(NOT(ISNUMBER(G14)),G14<0,G14<>INT(G14))),"ENTER TRANSACTIONS AS A WHOLE NUMBER","READY")))))))))),"FIX INVALID MARKET ENTRY"))
I15: =IF(COUNTA(A15:H15)=0,"",IFERROR(IF(A15="","ENTER MARKET DATE",IF(NOT(ISNUMBER(A15)),"ENTER A VALID DATE",IF(B15="","ENTER MARKET NAME",IF(NOT(ISTEXT(B15)),"ENTER MARKET NAME AS TEXT",IF(COUNTIFS($A$5:$A$54,A15,$B$5:$B$54,B15)>1,"REMOVE DUPLICATE MARKET DAY",IF(OR(NOT(ISNUMBER(C15)),C15<0),"ENTER BOOTH FEE AS 0 OR MORE",IF(OR(NOT(ISNUMBER(D15)),D15<0),"ENTER TRAVEL COST AS 0 OR MORE",IF(OR(NOT(ISNUMBER(E15)),E15<=0),"ENTER MARKET HOURS ABOVE 0",IF(OR(NOT(ISNUMBER(F15)),F15<0),"ENTER SALES AS 0 OR MORE",IF(AND(G15<>"",OR(NOT(ISNUMBER(G15)),G15<0,G15<>INT(G15))),"ENTER TRANSACTIONS AS A WHOLE NUMBER","READY")))))))))),"FIX INVALID MARKET ENTRY"))
I16: =IF(COUNTA(A16:H16)=0,"",IFERROR(IF(A16="","ENTER MARKET DATE",IF(NOT(ISNUMBER(A16)),"ENTER A VALID DATE",IF(B16="","ENTER MARKET NAME",IF(NOT(ISTEXT(B16)),"ENTER MARKET NAME AS TEXT",IF(COUNTIFS($A$5:$A$54,A16,$B$5:$B$54,B16)>1,"REMOVE DUPLICATE MARKET DAY",IF(OR(NOT(ISNUMBER(C16)),C16<0),"ENTER BOOTH FEE AS 0 OR MORE",IF(OR(NOT(ISNUMBER(D16)),D16<0),"ENTER TRAVEL COST AS 0 OR MORE",IF(OR(NOT(ISNUMBER(E16)),E16<=0),"ENTER MARKET HOURS ABOVE 0",IF(OR(NOT(ISNUMBER(F16)),F16<0),"ENTER SALES AS 0 OR MORE",IF(AND(G16<>"",OR(NOT(ISNUMBER(G16)),G16<0,G16<>INT(G16))),"ENTER TRANSACTIONS AS A WHOLE NUMBER","READY")))))))))),"FIX INVALID MARKET ENTRY"))
I17: =IF(COUNTA(A17:H17)=0,"",IFERROR(IF(A17="","ENTER MARKET DATE",IF(NOT(ISNUMBER(A17)),"ENTER A VALID DATE",IF(B17="","ENTER MARKET NAME",IF(NOT(ISTEXT(B17)),"ENTER MARKET NAME AS TEXT",IF(COUNTIFS($A$5:$A$54,A17,$B$5:$B$54,B17)>1,"REMOVE DUPLICATE MARKET DAY",IF(OR(NOT(ISNUMBER(C17)),C17<0),"ENTER BOOTH FEE AS 0 OR MORE",IF(OR(NOT(ISNUMBER(D17)),D17<0),"ENTER TRAVEL COST AS 0 OR MORE",IF(OR(NOT(ISNUMBER(E17)),E17<=0),"ENTER MARKET HOURS ABOVE 0",IF(OR(NOT(ISNUMBER(F17)),F17<0),"ENTER SALES AS 0 OR MORE",IF(AND(G17<>"",OR(NOT(ISNUMBER(G17)),G17<0,G17<>INT(G17))),"ENTER TRANSACTIONS AS A WHOLE NUMBER","READY")))))))))),"FIX INVALID MARKET ENTRY"))
I18: =IF(COUNTA(A18:H18)=0,"",IFERROR(IF(A18="","ENTER MARKET DATE",IF(NOT(ISNUMBER(A18)),"ENTER A VALID DATE",IF(B18="","ENTER MARKET NAME",IF(NOT(ISTEXT(B18)),"ENTER MARKET NAME AS TEXT",IF(COUNTIFS($A$5:$A$54,A18,$B$5:$B$54,B18)>1,"REMOVE DUPLICATE MARKET DAY",IF(OR(NOT(ISNUMBER(C18)),C18<0),"ENTER BOOTH FEE AS 0 OR MORE",IF(OR(NOT(ISNUMBER(D18)),D18<0),"ENTER TRAVEL COST AS 0 OR MORE",IF(OR(NOT(ISNUMBER(E18)),E18<=0),"ENTER MARKET HOURS ABOVE 0",IF(OR(NOT(ISNUMBER(F18)),F18<0),"ENTER SALES AS 0 OR MORE",IF(AND(G18<>"",OR(NOT(ISNUMBER(G18)),G18<0,G18<>INT(G18))),"ENTER TRANSACTIONS AS A WHOLE NUMBER","READY")))))))))),"FIX INVALID MARKET ENTRY"))
I19: =IF(COUNTA(A19:H19)=0,"",IFERROR(IF(A19="","ENTER MARKET DATE",IF(NOT(ISNUMBER(A19)),"ENTER A VALID DATE",IF(B19="","ENTER MARKET NAME",IF(NOT(ISTEXT(B19)),"ENTER MARKET NAME AS TEXT",IF(COUNTIFS($A$5:$A$54,A19,$B$5:$B$54,B19)>1,"REMOVE DUPLICATE MARKET DAY",IF(OR(NOT(ISNUMBER(C19)),C19<0),"ENTER BOOTH FEE AS 0 OR MORE",IF(OR(NOT(ISNUMBER(D19)),D19<0),"ENTER TRAVEL COST AS 0 OR MORE",IF(OR(NOT(ISNUMBER(E19)),E19<=0),"ENTER MARKET HOURS ABOVE 0",IF(OR(NOT(ISNUMBER(F19)),F19<0),"ENTER SALES AS 0 OR MORE",IF(AND(G19<>"",OR(NOT(ISNUMBER(G19)),G19<0,G19<>INT(G19))),"ENTER TRANSACTIONS AS A WHOLE NUMBER","READY")))))))))),"FIX INVALID MARKET ENTRY"))
... I54: =IF(COUNTA(A54:H54)=0,"",IFERROR(IF(A54="","ENTER MARKET DATE",IF(NOT(ISNUMBER(A54)),"ENTER A VALID DATE",IF(B54="","ENTER MARKET NAME",IF(NOT(ISTEXT(B54)),"ENTER MARKET NAME AS TEXT",IF(COUNTIFS($A$5:$A$54,A54,$B$5:$B$54,B54)>1,"REMOVE DUPLICATE MARKET DAY",IF(OR(NOT(ISNUMBER(C54)),C54<0),"ENTER BOOTH FEE AS 0 OR MORE",IF(OR(NOT(ISNUMBER(D54)),D54<0),"ENTER TRAVEL COST AS 0 OR MORE",IF(OR(NOT(ISNUMBER(E54)),E54<=0),"ENTER MARKET HOURS ABOVE 0",IF(OR(NOT(ISNUMBER(F54)),F54<0),"ENTER SALES AS 0 OR MORE",IF(AND(G54<>"",OR(NOT(ISNUMBER(G54)),G54<0,G54<>INT(G54))),"ENTER TRANSACTIONS AS A WHOLE NUMBER","READY")))))))))),"FIX INVALID MARKET ENTRY"))

Sheet Product Sales
A1: Product Sales by Market
A2: Enter one row per product batch. Product Work Hours × Value of Your Time / Hour is included in entered costs; market booth fee + travel is divided evenly across READY product rows for that event.
A3: SAMPLE DATA — rows 5 to 10 below are examples. Delete them before entering your own product sales.
A4: Market Date | B4: Market Name | C4: Product Batch | D4: Units Brought | E4: Units Sold | F4: Sales | G4: Ingredients Cost | H4: Packaging Cost | I4: Product Work Hours | J4: Value of Your Time / Hour | K4: Share of Booth + Travel | L4: Total Entered Cost | M4: Profit After Entered Costs | N4: Profit Margin | O4: Stock Sold % | P4: Profit per Product Work Hour | Q4: Target Check | R4: Input Check / What to Fix
A5: 46250 | B5: Saturday Market | C5: Lavender soap B-14 | D5: 36 | E5: 29 | F5: 232 | G5: 48 | H5: 18 | I5: 3.5 | J5: 20 | K5: =IF(R5<>"READY","",IFERROR(ROUND((ROUND(SUMIFS('Market Days'!$C$5:$C$54,'Market Days'!$A$5:$A$54,A5,'Market Days'!$B$5:$B$54,B5,'Market Days'!$I$5:$I$54,"READY"),2)+ROUND(SUMIFS('Market Days'!$D$5:$D$54,'Market Days'!$A$5:$A$54,A5,'Market Days'!$B$5:$B$54,B5,'Market Days'!$I$5:$I$54,"READY"),2))/COUNTIFS($A$5:$A$104,A5,$B$5:$B$104,B5,$R$5:$R$104,"READY"),2),"")) -> 49.5 | L5: =IF(R5<>"READY","",IFERROR(ROUND(ROUND(G5,2)+ROUND(H5,2)+ROUND(I5*ROUND(J5,2),2)+K5,2),"")) -> 185.5 | M5: =IF(R5<>"READY","",IFERROR(ROUND(ROUND(F5,2)-L5,2),"")) -> 46.5 | N5: =IF(R5<>"READY","",IFERROR(IF(ROUND(F5,2)=0,"",M5/ROUND(F5,2)),"")) -> 0.20043103 | O5: =IF(R5<>"READY","",IFERROR(E5/D5,"")) -> 0.80555556 | P5: =IF(R5<>"READY","",IFERROR(IF(I5=0,"",M5/I5),"")) -> 13.285714 | Q5: =IF(COUNTA(A5:J5)=0,"",IF(OR(R5<>"READY",COUNTIF(Targets!$D$5:$D$7,"READY")<>3),"NEEDS REVIEW",IFERROR(IF(AND(N5<>"",P5<>"",O5<>"",ROUND(N5,3)>=ROUND(Targets!$B$5,3),ROUND(P5,2)>=ROUND(Targets!$B$6,2),ROUND(O5,3)>=ROUND(Targets!$B$7,3)),"MEETS TARGETS","REVIEW"),"REVIEW"))) -> REVIEW | R5: =IF(COUNTA(A5:J5)=0,"",IFERROR(IF(A5="","ENTER MARKET DATE",IF(NOT(ISNUMBER(A5)),"ENTER A VALID DATE",IF(B5="","ENTER MARKET NAME",IF(C5="","ENTER PRODUCT BATCH",IF(COUNTIFS($A$5:$A$104,A5,$B$5:$B$104,B5,$C$5:$C$104,C5)>1,"REMOVE DUPLICATE PRODUCT ROW",IF(OR(NOT(ISNUMBER(D5)),D5<=0,D5<>INT(D5)),"ENTER UNITS BROUGHT AS A POSITIVE WHOLE NUMBER",IF(OR(NOT(ISNUMBER(E5)),E5<0,E5<>INT(E5),E5>D5),"CHECK WHOLE UNITS SOLD",IF(OR(NOT(ISNUMBER(F5)),F5<0),"ENTER SALES AS 0 OR MORE",IF(OR(NOT(ISNUMBER(G5)),G5<0),"ENTER INGREDIENT COST AS 0 OR MORE",IF(OR(NOT(ISNUMBER(H5)),H5<0),"ENTER PACKAGING COST AS 0 OR MORE",IF(OR(NOT(ISNUMBER(I5)),I5<0),"ENTER PRODUCT WORK HOURS AS 0 OR MORE",IF(OR(NOT(ISNUMBER(J5)),J5<0),"ENTER TIME VALUE AS 0 OR MORE",IF(COUNTIFS('Market Days'!$A$5:$A$54,A5,'Market Days'!$B$5:$B$54,B5,'Market Days'!$I$5:$I$54,"READY")<>1,"FIX OR ADD MATCHING MARKET DAY","READY"))))))))))))),"FIX INVALID PRODUCT ENTRY")) -> READY
A6: 46250 | B6: Saturday Market | C6: Citrus candle C-08 | D6: 24 | E6: 17 | F6: 255 | G6: 72 | H6: 21 | I6: 2.5 | J6: 20 | K6: =IF(R6<>"READY","",IFERROR(ROUND((ROUND(SUMIFS('Market Days'!$C$5:$C$54,'Market Days'!$A$5:$A$54,A6,'Market Days'!$B$5:$B$54,B6,'Market Days'!$I$5:$I$54,"READY"),2)+ROUND(SUMIFS('Market Days'!$D$5:$D$54,'Market Days'!$A$5:$A$54,A6,'Market Days'!$B$5:$B$54,B6,'Market Days'!$I$5:$I$54,"READY"),2))/COUNTIFS($A$5:$A$104,A6,$B$5:$B$104,B6,$R$5:$R$104,"READY"),2),"")) -> 49.5 | L6: =IF(R6<>"READY","",IFERROR(ROUND(ROUND(G6,2)+ROUND(H6,2)+ROUND(I6*ROUND(J6,2),2)+K6,2),"")) -> 192.5 | M6: =IF(R6<>"READY","",IFERROR(ROUND(ROUND(F6,2)-L6,2),"")) -> 62.5 | N6: =IF(R6<>"READY","",IFERROR(IF(ROUND(F6,2)=0,"",M6/ROUND(F6,2)),"")) -> 0.24509804 | O6: =IF(R6<>"READY","",IFERROR(E6/D6,"")) -> 0.70833333 | P6: =IF(R6<>"READY","",IFERROR(IF(I6=0,"",M6/I6),"")) -> 25 | Q6: =IF(COUNTA(A6:J6)=0,"",IF(OR(R6<>"READY",COUNTIF(Targets!$D$5:$D$7,"READY")<>3),"NEEDS REVIEW",IFERROR(IF(AND(N6<>"",P6<>"",O6<>"",ROUND(N6,3)>=ROUND(Targets!$B$5,3),ROUND(P6,2)>=ROUND(Targets!$B$6,2),ROUND(O6,3)>=ROUND(Targets!$B$7,3)),"MEETS TARGETS","REVIEW"),"REVIEW"))) -> REVIEW | R6: =IF(COUNTA(A6:J6)=0,"",IFERROR(IF(A6="","ENTER MARKET DATE",IF(NOT(ISNUMBER(A6)),"ENTER A VALID DATE",IF(B6="","ENTER MARKET NAME",IF(C6="","ENTER PRODUCT BATCH",IF(COUNTIFS($A$5:$A$104,A6,$B$5:$B$104,B6,$C$5:$C$104,C6)>1,"REMOVE DUPLICATE PRODUCT ROW",IF(OR(NOT(ISNUMBER(D6)),D6<=0,D6<>INT(D6)),"ENTER UNITS BROUGHT AS A POSITIVE WHOLE NUMBER",IF(OR(NOT(ISNUMBER(E6)),E6<0,E6<>INT(E6),E6>D6),"CHECK WHOLE UNITS SOLD",IF(OR(NOT(ISNUMBER(F6)),F6<0),"ENTER SALES AS 0 OR MORE",IF(OR(NOT(ISNUMBER(G6)),G6<0),"ENTER INGREDIENT COST AS 0 OR MORE",IF(OR(NOT(ISNUMBER(H6)),H6<0),"ENTER PACKAGING COST AS 0 OR MORE",IF(OR(NOT(ISNUMBER(I6)),I6<0),"ENTER PRODUCT WORK HOURS AS 0 OR MORE",IF(OR(NOT(ISNUMBER(J6)),J6<0),"ENTER TIME VALUE AS 0 OR MORE",IF(COUNTIFS('Market Days'!$A$5:$A$54,A6,'Market Days'!$B$5:$B$54,B6,'Market Days'!$I$5:$I$54,"READY")<>1,"FIX OR ADD MATCHING MARKET DAY","READY"))))))))))))),"FIX INVALID PRODUCT ENTRY")) -> READY
A7: 46257 | B7: Riverside Pop-Up | C7: Lavender soap B-15 | D7: 30 | E7: 26 | F7: 208 | G7: 40 | H7: 15 | I7: 3 | J7: 20 | K7: =IF(R7<>"READY","",IFERROR(ROUND((ROUND(SUMIFS('Market Days'!$C$5:$C$54,'Market Days'!$A$5:$A$54,A7,'Market Days'!$B$5:$B$54,B7,'Market Days'!$I$5:$I$54,"READY"),2)+ROUND(SUMIFS('Market Days'!$D$5:$D$54,'Market Days'!$A$5:$A$54,A7,'Market Days'!$B$5:$B$54,B7,'Market Days'!$I$5:$I$54,"READY"),2))/COUNTIFS($A$5:$A$104,A7,$B$5:$B$104,B7,$R$5:$R$104,"READY"),2),"")) -> 31.5 | L7: =IF(R7<>"READY","",IFERROR(ROUND(ROUND(G7,2)+ROUND(H7,2)+ROUND(I7*ROUND(J7,2),2)+K7,2),"")) -> 146.5 | M7: =IF(R7<>"READY","",IFERROR(ROUND(ROUND(F7,2)-L7,2),"")) -> 61.5 | N7: =IF(R7<>"READY","",IFERROR(IF(ROUND(F7,2)=0,"",M7/ROUND(F7,2)),"")) -> 0.29567308 | O7: =IF(R7<>"READY","",IFERROR(E7/D7,"")) -> 0.86666667 | P7: =IF(R7<>"READY","",IFERROR(IF(I7=0,"",M7/I7),"")) -> 20.5 | Q7: =IF(COUNTA(A7:J7)=0,"",IF(OR(R7<>"READY",COUNTIF(Targets!$D$5:$D$7,"READY")<>3),"NEEDS REVIEW",IFERROR(IF(AND(N7<>"",P7<>"",O7<>"",ROUND(N7,3)>=ROUND(Targets!$B$5,3),ROUND(P7,2)>=ROUND(Targets!$B$6,2),ROUND(O7,3)>=ROUND(Targets!$B$7,3)),"MEETS TARGETS","REVIEW"),"REVIEW"))) -> REVIEW | R7: =IF(COUNTA(A7:J7)=0,"",IFERROR(IF(A7="","ENTER MARKET DATE",IF(NOT(ISNUMBER(A7)),"ENTER A VALID DATE",IF(B7="","ENTER MARKET NAME",IF(C7="","ENTER PRODUCT BATCH",IF(COUNTIFS($A$5:$A$104,A7,$B$5:$B$104,B7,$C$5:$C$104,C7)>1,"REMOVE DUPLICATE PRODUCT ROW",IF(OR(NOT(ISNUMBER(D7)),D7<=0,D7<>INT(D7)),"ENTER UNITS BROUGHT AS A POSITIVE WHOLE NUMBER",IF(OR(NOT(ISNUMBER(E7)),E7<0,E7<>INT(E7),E7>D7),"CHECK WHOLE UNITS SOLD",IF(OR(NOT(ISNUMBER(F7)),F7<0),"ENTER SALES AS 0 OR MORE",IF(OR(NOT(ISNUMBER(G7)),G7<0),"ENTER INGREDIENT COST AS 0 OR MORE",IF(OR(NOT(ISNUMBER(H7)),H7<0),"ENTER PACKAGING COST AS 0 OR MORE",IF(OR(NOT(ISNUMBER(I7)),I7<0),"ENTER PRODUCT WORK HOURS AS 0 OR MORE",IF(OR(NOT(ISNUMBER(J7)),J7<0),"ENTER TIME VALUE AS 0 OR MORE",IF(COUNTIFS('Market Days'!$A$5:$A$54,A7,'Market Days'!$B$5:$B$54,B7,'Market Days'!$I$5:$I$54,"READY")<>1,"FIX OR ADD MATCHING MARKET DAY","READY"))))))))))))),"FIX INVALID PRODUCT ENTRY")) -> READY
A8: 46257 | B8: Riverside Pop-Up | C8: Citrus candle C-09 | D8: 20 | E8: 18 | F8: 270 | G8: 60 | H8: 18 | I8: 2 | J8: 20 | K8: =IF(R8<>"READY","",IFERROR(ROUND((ROUND(SUMIFS('Market Days'!$C$5:$C$54,'Market Days'!$A$5:$A$54,A8,'Market Days'!$B$5:$B$54,B8,'Market Days'!$I$5:$I$54,"READY"),2)+ROUND(SUMIFS('Market Days'!$D$5:$D$54,'Market Days'!$A$5:$A$54,A8,'Market Days'!$B$5:$B$54,B8,'Market Days'!$I$5:$I$54,"READY"),2))/COUNTIFS($A$5:$A$104,A8,$B$5:$B$104,B8,$R$5:$R$104,"READY"),2),"")) -> 31.5 | L8: =IF(R8<>"READY","",IFERROR(ROUND(ROUND(G8,2)+ROUND(H8,2)+ROUND(I8*ROUND(J8,2),2)+K8,2),"")) -> 149.5 | M8: =IF(R8<>"READY","",IFERROR(ROUND(ROUND(F8,2)-L8,2),"")) -> 120.5 | N8: =IF(R8<>"READY","",IFERROR(IF(ROUND(F8,2)=0,"",M8/ROUND(F8,2)),"")) -> 0.4462963 | O8: =IF(R8<>"READY","",IFERROR(E8/D8,"")) -> 0.9 | P8: =IF(R8<>"READY","",IFERROR(IF(I8=0,"",M8/I8),"")) -> 60.25 | Q8: =IF(COUNTA(A8:J8)=0,"",IF(OR(R8<>"READY",COUNTIF(Targets!$D$5:$D$7,"READY")<>3),"NEEDS REVIEW",IFERROR(IF(AND(N8<>"",P8<>"",O8<>"",ROUND(N8,3)>=ROUND(Targets!$B$5,3),ROUND(P8,2)>=ROUND(Targets!$B$6,2),ROUND(O8,3)>=ROUND(Targets!$B$7,3)),"MEETS TARGETS","REVIEW"),"REVIEW"))) -> MEETS TARGETS | R8: =IF(COUNTA(A8:J8)=0,"",IFERROR(IF(A8="","ENTER MARKET DATE",IF(NOT(ISNUMBER(A8)),"ENTER A VALID DATE",IF(B8="","ENTER MARKET NAME",IF(C8="","ENTER PRODUCT BATCH",IF(COUNTIFS($A$5:$A$104,A8,$B$5:$B$104,B8,$C$5:$C$104,C8)>1,"REMOVE DUPLICATE PRODUCT ROW",IF(OR(NOT(ISNUMBER(D8)),D8<=0,D8<>INT(D8)),"ENTER UNITS BROUGHT AS A POSITIVE WHOLE NUMBER",IF(OR(NOT(ISNUMBER(E8)),E8<0,E8<>INT(E8),E8>D8),"CHECK WHOLE UNITS SOLD",IF(OR(NOT(ISNUMBER(F8)),F8<0),"ENTER SALES AS 0 OR MORE",IF(OR(NOT(ISNUMBER(G8)),G8<0),"ENTER INGREDIENT COST AS 0 OR MORE",IF(OR(NOT(ISNUMBER(H8)),H8<0),"ENTER PACKAGING COST AS 0 OR MORE",IF(OR(NOT(ISNUMBER(I8)),I8<0),"ENTER PRODUCT WORK HOURS AS 0 OR MORE",IF(OR(NOT(ISNUMBER(J8)),J8<0),"ENTER TIME VALUE AS 0 OR MORE",IF(COUNTIFS('Market Days'!$A$5:$A$54,A8,'Market Days'!$B$5:$B$54,B8,'Market Days'!$I$5:$I$54,"READY")<>1,"FIX OR ADD MATCHING MARKET DAY","READY"))))))))))))),"FIX INVALID PRODUCT ENTRY")) -> READY
A9: 46264 | B9: Night Bazaar | C9: Lavender soap B-16 | D9: 40 | E9: 28 | F9: 224 | G9: 54 | H9: 20 | I9: 4 | J9: 20 | K9: =IF(R9<>"READY","",IFERROR(ROUND((ROUND(SUMIFS('Market Days'!$C$5:$C$54,'Market Days'!$A$5:$A$54,A9,'Market Days'!$B$5:$B$54,B9,'Market Days'!$I$5:$I$54,"READY"),2)+ROUND(SUMIFS('Market Days'!$D$5:$D$54,'Market Days'!$A$5:$A$54,A9,'Market Days'!$B$5:$B$54,B9,'Market Days'!$I$5:$I$54,"READY"),2))/COUNTIFS($A$5:$A$104,A9,$B$5:$B$104,B9,$R$5:$R$104,"READY"),2),"")) -> 70 | L9: =IF(R9<>"READY","",IFERROR(ROUND(ROUND(G9,2)+ROUND(H9,2)+ROUND(I9*ROUND(J9,2),2)+K9,2),"")) -> 224 | M9: =IF(R9<>"READY","",IFERROR(ROUND(ROUND(F9,2)-L9,2),"")) -> 0 | N9: =IF(R9<>"READY","",IFERROR(IF(ROUND(F9,2)=0,"",M9/ROUND(F9,2)),"")) -> 0 | O9: =IF(R9<>"READY","",IFERROR(E9/D9,"")) -> 0.7 | P9: =IF(R9<>"READY","",IFERROR(IF(I9=0,"",M9/I9),"")) -> 0 | Q9: =IF(COUNTA(A9:J9)=0,"",IF(OR(R9<>"READY",COUNTIF(Targets!$D$5:$D$7,"READY")<>3),"NEEDS REVIEW",IFERROR(IF(AND(N9<>"",P9<>"",O9<>"",ROUND(N9,3)>=ROUND(Targets!$B$5,3),ROUND(P9,2)>=ROUND(Targets!$B$6,2),ROUND(O9,3)>=ROUND(Targets!$B$7,3)),"MEETS TARGETS","REVIEW"),"REVIEW"))) -> REVIEW | R9: =IF(COUNTA(A9:J9)=0,"",IFERROR(IF(A9="","ENTER MARKET DATE",IF(NOT(ISNUMBER(A9)),"ENTER A VALID DATE",IF(B9="","ENTER MARKET NAME",IF(C9="","ENTER PRODUCT BATCH",IF(COUNTIFS($A$5:$A$104,A9,$B$5:$B$104,B9,$C$5:$C$104,C9)>1,"REMOVE DUPLICATE PRODUCT ROW",IF(OR(NOT(ISNUMBER(D9)),D9<=0,D9<>INT(D9)),"ENTER UNITS BROUGHT AS A POSITIVE WHOLE NUMBER",IF(OR(NOT(ISNUMBER(E9)),E9<0,E9<>INT(E9),E9>D9),"CHECK WHOLE UNITS SOLD",IF(OR(NOT(ISNUMBER(F9)),F9<0),"ENTER SALES AS 0 OR MORE",IF(OR(NOT(ISNUMBER(G9)),G9<0),"ENTER INGREDIENT COST AS 0 OR MORE",IF(OR(NOT(ISNUMBER(H9)),H9<0),"ENTER PACKAGING COST AS 0 OR MORE",IF(OR(NOT(ISNUMBER(I9)),I9<0),"ENTER PRODUCT WORK HOURS AS 0 OR MORE",IF(OR(NOT(ISNUMBER(J9)),J9<0),"ENTER TIME VALUE AS 0 OR MORE",IF(COUNTIFS('Market Days'!$A$5:$A$54,A9,'Market Days'!$B$5:$B$54,B9,'Market Days'!$I$5:$I$54,"READY")<>1,"FIX OR ADD MATCHING MARKET DAY","READY"))))))))))))),"FIX INVALID PRODUCT ENTRY")) -> READY
A10: 46264 | B10: Night Bazaar | C10: Citrus candle C-10 | D10: 30 | E10: 19 | F10: 285 | G10: 80 | H10: 24 | I10: 3 | J10: 20 | K10: =IF(R10<>"READY","",IFERROR(ROUND((ROUND(SUMIFS('Market Days'!$C$5:$C$54,'Market Days'!$A$5:$A$54,A10,'Market Days'!$B$5:$B$54,B10,'Market Days'!$I$5:$I$54,"READY"),2)+ROUND(SUMIFS('Market Days'!$D$5:$D$54,'Market Days'!$A$5:$A$54,A10,'Market Days'!$B$5:$B$54,B10,'Market Days'!$I$5:$I$54,"READY"),2))/COUNTIFS($A$5:$A$104,A10,$B$5:$B$104,B10,$R$5:$R$104,"READY"),2),"")) -> 70 | L10: =IF(R10<>"READY","",IFERROR(ROUND(ROUND(G10,2)+ROUND(H10,2)+ROUND(I10*ROUND(J10,2),2)+K10,2),"")) -> 234 | M10: =IF(R10<>"READY","",IFERROR(ROUND(ROUND(F10,2)-L10,2),"")) -> 51 | N10: =IF(R10<>"READY","",IFERROR(IF(ROUND(F10,2)=0,"",M10/ROUND(F10,2)),"")) -> 0.17894737 | O10: =IF(R10<>"READY","",IFERROR(E10/D10,"")) -> 0.63333333 | P10: =IF(R10<>"READY","",IFERROR(IF(I10=0,"",M10/I10),"")) -> 17 | Q10: =IF(COUNTA(A10:J10)=0,"",IF(OR(R10<>"READY",COUNTIF(Targets!$D$5:$D$7,"READY")<>3),"NEEDS REVIEW",IFERROR(IF(AND(N10<>"",P10<>"",O10<>"",ROUND(N10,3)>=ROUND(Targets!$B$5,3),ROUND(P10,2)>=ROUND(Targets!$B$6,2),ROUND(O10,3)>=ROUND(Targets!$B$7,3)),"MEETS TARGETS","REVIEW"),"REVIEW"))) -> REVIEW | R10: =IF(COUNTA(A10:J10)=0,"",IFERROR(IF(A10="","ENTER MARKET DATE",IF(NOT(ISNUMBER(A10)),"ENTER A VALID DATE",IF(B10="","ENTER MARKET NAME",IF(C10="","ENTER PRODUCT BATCH",IF(COUNTIFS($A$5:$A$104,A10,$B$5:$B$104,B10,$C$5:$C$104,C10)>1,"REMOVE DUPLICATE PRODUCT ROW",IF(OR(NOT(ISNUMBER(D10)),D10<=0,D10<>INT(D10)),"ENTER UNITS BROUGHT AS A POSITIVE WHOLE NUMBER",IF(OR(NOT(ISNUMBER(E10)),E10<0,E10<>INT(E10),E10>D10),"CHECK WHOLE UNITS SOLD",IF(OR(NOT(ISNUMBER(F10)),F10<0),"ENTER SALES AS 0 OR MORE",IF(OR(NOT(ISNUMBER(G10)),G10<0),"ENTER INGREDIENT COST AS 0 OR MORE",IF(OR(NOT(ISNUMBER(H10)),H10<0),"ENTER PACKAGING COST AS 0 OR MORE",IF(OR(NOT(ISNUMBER(I10)),I10<0),"ENTER PRODUCT WORK HOURS AS 0 OR MORE",IF(OR(NOT(ISNUMBER(J10)),J10<0),"ENTER TIME VALUE AS 0 OR MORE",IF(COUNTIFS('Market Days'!$A$5:$A$54,A10,'Market Days'!$B$5:$B$54,B10,'Market Days'!$I$5:$I$54,"READY")<>1,"FIX OR ADD MATCHING MARKET DAY","READY"))))))))))))),"FIX INVALID PRODUCT ENTRY")) -> READY
K11: =IF(R11<>"READY","",IFERROR(ROUND((ROUND(SUMIFS('Market Days'!$C$5:$C$54,'Market Days'!$A$5:$A$54,A11,'Market Days'!$B$5:$B$54,B11,'Market Days'!$I$5:$I$54,"READY"),2)+ROUND(SUMIFS('Market Days'!$D$5:$D$54,'Market Days'!$A$5:$A$54,A11,'Market Days'!$B$5:$B$54,B11,'Market Days'!$I$5:$I$54,"READY"),2))/COUNTIFS($A$5:$A$104,A11,$B$5:$B$104,B11,$R$5:$R$104,"READY"),2),"")) | L11: =IF(R11<>"READY","",IFERROR(ROUND(ROUND(G11,2)+ROUND(H11,2)+ROUND(I11*ROUND(J11,2),2)+K11,2),"")) | M11: =IF(R11<>"READY","",IFERROR(ROUND(ROUND(F11,2)-L11,2),"")) | N11: =IF(R11<>"READY","",IFERROR(IF(ROUND(F11,2)=0,"",M11/ROUND(F11,2)),"")) | O11: =IF(R11<>"READY","",IFERROR(E11/D11,"")) | P11: =IF(R11<>"READY","",IFERROR(IF(I11=0,"",M11/I11),"")) | Q11: =IF(COUNTA(A11:J11)=0,"",IF(OR(R11<>"READY",COUNTIF(Targets!$D$5:$D$7,"READY")<>3),"NEEDS REVIEW",IFERROR(IF(AND(N11<>"",P11<>"",O11<>"",ROUND(N11,3)>=ROUND(Targets!$B$5,3),ROUND(P11,2)>=ROUND(Targets!$B$6,2),ROUND(O11,3)>=ROUND(Targets!$B$7,3)),"MEETS TARGETS","REVIEW"),"REVIEW"))) | R11: =IF(COUNTA(A11:J11)=0,"",IFERROR(IF(A11="","ENTER MARKET DATE",IF(NOT(ISNUMBER(A11)),"ENTER A VALID DATE",IF(B11="","ENTER MARKET NAME",IF(C11="","ENTER PRODUCT BATCH",IF(COUNTIFS($A$5:$A$104,A11,$B$5:$B$104,B11,$C$5:$C$104,C11)>1,"REMOVE DUPLICATE PRODUCT ROW",IF(OR(NOT(ISNUMBER(D11)),D11<=0,D11<>INT(D11)),"ENTER UNITS BROUGHT AS A POSITIVE WHOLE NUMBER",IF(OR(NOT(ISNUMBER(E11)),E11<0,E11<>INT(E11),E11>D11),"CHECK WHOLE UNITS SOLD",IF(OR(NOT(ISNUMBER(F11)),F11<0),"ENTER SALES AS 0 OR MORE",IF(OR(NOT(ISNUMBER(G11)),G11<0),"ENTER INGREDIENT COST AS 0 OR MORE",IF(OR(NOT(ISNUMBER(H11)),H11<0),"ENTER PACKAGING COST AS 0 OR MORE",IF(OR(NOT(ISNUMBER(I11)),I11<0),"ENTER PRODUCT WORK HOURS AS 0 OR MORE",IF(OR(NOT(ISNUMBER(J11)),J11<0),"ENTER TIME VALUE AS 0 OR MORE",IF(COUNTIFS('Market Days'!$A$5:$A$54,A11,'Market Days'!$B$5:$B$54,B11,'Market Days'!$I$5:$I$54,"READY")<>1,"FIX OR ADD MATCHING MARKET DAY","READY"))))))))))))),"FIX INVALID PRODUCT ENTRY"))
K12: =IF(R12<>"READY","",IFERROR(ROUND((ROUND(SUMIFS('Market Days'!$C$5:$C$54,'Market Days'!$A$5:$A$54,A12,'Market Days'!$B$5:$B$54,B12,'Market Days'!$I$5:$I$54,"READY"),2)+ROUND(SUMIFS('Market Days'!$D$5:$D$54,'Market Days'!$A$5:$A$54,A12,'Market Days'!$B$5:$B$54,B12,'Market Days'!$I$5:$I$54,"READY"),2))/COUNTIFS($A$5:$A$104,A12,$B$5:$B$104,B12,$R$5:$R$104,"READY"),2),"")) | L12: =IF(R12<>"READY","",IFERROR(ROUND(ROUND(G12,2)+ROUND(H12,2)+ROUND(I12*ROUND(J12,2),2)+K12,2),"")) | M12: =IF(R12<>"READY","",IFERROR(ROUND(ROUND(F12,2)-L12,2),"")) | N12: =IF(R12<>"READY","",IFERROR(IF(ROUND(F12,2)=0,"",M12/ROUND(F12,2)),"")) | O12: =IF(R12<>"READY","",IFERROR(E12/D12,"")) | P12: =IF(R12<>"READY","",IFERROR(IF(I12=0,"",M12/I12),"")) | Q12: =IF(COUNTA(A12:J12)=0,"",IF(OR(R12<>"READY",COUNTIF(Targets!$D$5:$D$7,"READY")<>3),"NEEDS REVIEW",IFERROR(IF(AND(N12<>"",P12<>"",O12<>"",ROUND(N12,3)>=ROUND(Targets!$B$5,3),ROUND(P12,2)>=ROUND(Targets!$B$6,2),ROUND(O12,3)>=ROUND(Targets!$B$7,3)),"MEETS TARGETS","REVIEW"),"REVIEW"))) | R12: =IF(COUNTA(A12:J12)=0,"",IFERROR(IF(A12="","ENTER MARKET DATE",IF(NOT(ISNUMBER(A12)),"ENTER A VALID DATE",IF(B12="","ENTER MARKET NAME",IF(C12="","ENTER PRODUCT BATCH",IF(COUNTIFS($A$5:$A$104,A12,$B$5:$B$104,B12,$C$5:$C$104,C12)>1,"REMOVE DUPLICATE PRODUCT ROW",IF(OR(NOT(ISNUMBER(D12)),D12<=0,D12<>INT(D12)),"ENTER UNITS BROUGHT AS A POSITIVE WHOLE NUMBER",IF(OR(NOT(ISNUMBER(E12)),E12<0,E12<>INT(E12),E12>D12),"CHECK WHOLE UNITS SOLD",IF(OR(NOT(ISNUMBER(F12)),F12<0),"ENTER SALES AS 0 OR MORE",IF(OR(NOT(ISNUMBER(G12)),G12<0),"ENTER INGREDIENT COST AS 0 OR MORE",IF(OR(NOT(ISNUMBER(H12)),H12<0),"ENTER PACKAGING COST AS 0 OR MORE",IF(OR(NOT(ISNUMBER(I12)),I12<0),"ENTER PRODUCT WORK HOURS AS 0 OR MORE",IF(OR(NOT(ISNUMBER(J12)),J12<0),"ENTER TIME VALUE AS 0 OR MORE",IF(COUNTIFS('Market Days'!$A$5:$A$54,A12,'Market Days'!$B$5:$B$54,B12,'Market Days'!$I$5:$I$54,"READY")<>1,"FIX OR ADD MATCHING MARKET DAY","READY"))))))))))))),"FIX INVALID PRODUCT ENTRY"))
K13: =IF(R13<>"READY","",IFERROR(ROUND((ROUND(SUMIFS('Market Days'!$C$5:$C$54,'Market Days'!$A$5:$A$54,A13,'Market Days'!$B$5:$B$54,B13,'Market Days'!$I$5:$I$54,"READY"),2)+ROUND(SUMIFS('Market Days'!$D$5:$D$54,'Market Days'!$A$5:$A$54,A13,'Market Days'!$B$5:$B$54,B13,'Market Days'!$I$5:$I$54,"READY"),2))/COUNTIFS($A$5:$A$104,A13,$B$5:$B$104,B13,$R$5:$R$104,"READY"),2),"")) | L13: =IF(R13<>"READY","",IFERROR(ROUND(ROUND(G13,2)+ROUND(H13,2)+ROUND(I13*ROUND(J13,2),2)+K13,2),"")) | M13: =IF(R13<>"READY","",IFERROR(ROUND(ROUND(F13,2)-L13,2),"")) | N13: =IF(R13<>"READY","",IFERROR(IF(ROUND(F13,2)=0,"",M13/ROUND(F13,2)),"")) | O13: =IF(R13<>"READY","",IFERROR(E13/D13,"")) | P13: =IF(R13<>"READY","",IFERROR(IF(I13=0,"",M13/I13),"")) | Q13: =IF(COUNTA(A13:J13)=0,"",IF(OR(R13<>"READY",COUNTIF(Targets!$D$5:$D$7,"READY")<>3),"NEEDS REVIEW",IFERROR(IF(AND(N13<>"",P13<>"",O13<>"",ROUND(N13,3)>=ROUND(Targets!$B$5,3),ROUND(P13,2)>=ROUND(Targets!$B$6,2),ROUND(O13,3)>=ROUND(Targets!$B$7,3)),"MEETS TARGETS","REVIEW"),"REVIEW"))) | R13: =IF(COUNTA(A13:J13)=0,"",IFERROR(IF(A13="","ENTER MARKET DATE",IF(NOT(ISNUMBER(A13)),"ENTER A VALID DATE",IF(B13="","ENTER MARKET NAME",IF(C13="","ENTER PRODUCT BATCH",IF(COUNTIFS($A$5:$A$104,A13,$B$5:$B$104,B13,$C$5:$C$104,C13)>1,"REMOVE DUPLICATE PRODUCT ROW",IF(OR(NOT(ISNUMBER(D13)),D13<=0,D13<>INT(D13)),"ENTER UNITS BROUGHT AS A POSITIVE WHOLE NUMBER",IF(OR(NOT(ISNUMBER(E13)),E13<0,E13<>INT(E13),E13>D13),"CHECK WHOLE UNITS SOLD",IF(OR(NOT(ISNUMBER(F13)),F13<0),"ENTER SALES AS 0 OR MORE",IF(OR(NOT(ISNUMBER(G13)),G13<0),"ENTER INGREDIENT COST AS 0 OR MORE",IF(OR(NOT(ISNUMBER(H13)),H13<0),"ENTER PACKAGING COST AS 0 OR MORE",IF(OR(NOT(ISNUMBER(I13)),I13<0),"ENTER PRODUCT WORK HOURS AS 0 OR MORE",IF(OR(NOT(ISNUMBER(J13)),J13<0),"ENTER TIME VALUE AS 0 OR MORE",IF(COUNTIFS('Market Days'!$A$5:$A$54,A13,'Market Days'!$B$5:$B$54,B13,'Market Days'!$I$5:$I$54,"READY")<>1,"FIX OR ADD MATCHING MARKET DAY","READY"))))))))))))),"FIX INVALID PRODUCT ENTRY"))
K14: =IF(R14<>"READY","",IFERROR(ROUND((ROUND(SUMIFS('Market Days'!$C$5:$C$54,'Market Days'!$A$5:$A$54,A14,'Market Days'!$B$5:$B$54,B14,'Market Days'!$I$5:$I$54,"READY"),2)+ROUND(SUMIFS('Market Days'!$D$5:$D$54,'Market Days'!$A$5:$A$54,A14,'Market Days'!$B$5:$B$54,B14,'Market Days'!$I$5:$I$54,"READY"),2))/COUNTIFS($A$5:$A$104,A14,$B$5:$B$104,B14,$R$5:$R$104,"READY"),2),"")) | L14: =IF(R14<>"READY","",IFERROR(ROUND(ROUND(G14,2)+ROUND(H14,2)+ROUND(I14*ROUND(J14,2),2)+K14,2),"")) | M14: =IF(R14<>"READY","",IFERROR(ROUND(ROUND(F14,2)-L14,2),"")) | N14: =IF(R14<>"READY","",IFERROR(IF(ROUND(F14,2)=0,"",M14/ROUND(F14,2)),"")) | O14: =IF(R14<>"READY","",IFERROR(E14/D14,"")) | P14: =IF(R14<>"READY","",IFERROR(IF(I14=0,"",M14/I14),"")) | Q14: =IF(COUNTA(A14:J14)=0,"",IF(OR(R14<>"READY",COUNTIF(Targets!$D$5:$D$7,"READY")<>3),"NEEDS REVIEW",IFERROR(IF(AND(N14<>"",P14<>"",O14<>"",ROUND(N14,3)>=ROUND(Targets!$B$5,3),ROUND(P14,2)>=ROUND(Targets!$B$6,2),ROUND(O14,3)>=ROUND(Targets!$B$7,3)),"MEETS TARGETS","REVIEW"),"REVIEW"))) | R14: =IF(COUNTA(A14:J14)=0,"",IFERROR(IF(A14="","ENTER MARKET DATE",IF(NOT(ISNUMBER(A14)),"ENTER A VALID DATE",IF(B14="","ENTER MARKET NAME",IF(C14="","ENTER PRODUCT BATCH",IF(COUNTIFS($A$5:$A$104,A14,$B$5:$B$104,B14,$C$5:$C$104,C14)>1,"REMOVE DUPLICATE PRODUCT ROW",IF(OR(NOT(ISNUMBER(D14)),D14<=0,D14<>INT(D14)),"ENTER UNITS BROUGHT AS A POSITIVE WHOLE NUMBER",IF(OR(NOT(ISNUMBER(E14)),E14<0,E14<>INT(E14),E14>D14),"CHECK WHOLE UNITS SOLD",IF(OR(NOT(ISNUMBER(F14)),F14<0),"ENTER SALES AS 0 OR MORE",IF(OR(NOT(ISNUMBER(G14)),G14<0),"ENTER INGREDIENT COST AS 0 OR MORE",IF(OR(NOT(ISNUMBER(H14)),H14<0),"ENTER PACKAGING COST AS 0 OR MORE",IF(OR(NOT(ISNUMBER(I14)),I14<0),"ENTER PRODUCT WORK HOURS AS 0 OR MORE",IF(OR(NOT(ISNUMBER(J14)),J14<0),"ENTER TIME VALUE AS 0 OR MORE",IF(COUNTIFS('Market Days'!$A$5:$A$54,A14,'Market Days'!$B$5:$B$54,B14,'Market Days'!$I$5:$I$54,"READY")<>1,"FIX OR ADD MATCHING MARKET DAY","READY"))))))))))))),"FIX INVALID PRODUCT ENTRY"))
K15: =IF(R15<>"READY","",IFERROR(ROUND((ROUND(SUMIFS('Market Days'!$C$5:$C$54,'Market Days'!$A$5:$A$54,A15,'Market Days'!$B$5:$B$54,B15,'Market Days'!$I$5:$I$54,"READY"),2)+ROUND(SUMIFS('Market Days'!$D$5:$D$54,'Market Days'!$A$5:$A$54,A15,'Market Days'!$B$5:$B$54,B15,'Market Days'!$I$5:$I$54,"READY"),2))/COUNTIFS($A$5:$A$104,A15,$B$5:$B$104,B15,$R$5:$R$104,"READY"),2),"")) | L15: =IF(R15<>"READY","",IFERROR(ROUND(ROUND(G15,2)+ROUND(H15,2)+ROUND(I15*ROUND(J15,2),2)+K15,2),"")) | M15: =IF(R15<>"READY","",IFERROR(ROUND(ROUND(F15,2)-L15,2),"")) | N15: =IF(R15<>"READY","",IFERROR(IF(ROUND(F15,2)=0,"",M15/ROUND(F15,2)),"")) | O15: =IF(R15<>"READY","",IFERROR(E15/D15,"")) | P15: =IF(R15<>"READY","",IFERROR(IF(I15=0,"",M15/I15),"")) | Q15: =IF(COUNTA(A15:J15)=0,"",IF(OR(R15<>"READY",COUNTIF(Targets!$D$5:$D$7,"READY")<>3),"NEEDS REVIEW",IFERROR(IF(AND(N15<>"",P15<>"",O15<>"",ROUND(N15,3)>=ROUND(Targets!$B$5,3),ROUND(P15,2)>=ROUND(Targets!$B$6,2),ROUND(O15,3)>=ROUND(Targets!$B$7,3)),"MEETS TARGETS","REVIEW"),"REVIEW"))) | R15: =IF(COUNTA(A15:J15)=0,"",IFERROR(IF(A15="","ENTER MARKET DATE",IF(NOT(ISNUMBER(A15)),"ENTER A VALID DATE",IF(B15="","ENTER MARKET NAME",IF(C15="","ENTER PRODUCT BATCH",IF(COUNTIFS($A$5:$A$104,A15,$B$5:$B$104,B15,$C$5:$C$104,C15)>1,"REMOVE DUPLICATE PRODUCT ROW",IF(OR(NOT(ISNUMBER(D15)),D15<=0,D15<>INT(D15)),"ENTER UNITS BROUGHT AS A POSITIVE WHOLE NUMBER",IF(OR(NOT(ISNUMBER(E15)),E15<0,E15<>INT(E15),E15>D15),"CHECK WHOLE UNITS SOLD",IF(OR(NOT(ISNUMBER(F15)),F15<0),"ENTER SALES AS 0 OR MORE",IF(OR(NOT(ISNUMBER(G15)),G15<0),"ENTER INGREDIENT COST AS 0 OR MORE",IF(OR(NOT(ISNUMBER(H15)),H15<0),"ENTER PACKAGING COST AS 0 OR MORE",IF(OR(NOT(ISNUMBER(I15)),I15<0),"ENTER PRODUCT WORK HOURS AS 0 OR MORE",IF(OR(NOT(ISNUMBER(J15)),J15<0),"ENTER TIME VALUE AS 0 OR MORE",IF(COUNTIFS('Market Days'!$A$5:$A$54,A15,'Market Days'!$B$5:$B$54,B15,'Market Days'!$I$5:$I$54,"READY")<>1,"FIX OR ADD MATCHING MARKET DAY","READY"))))))))))))),"FIX INVALID PRODUCT ENTRY"))
K16: =IF(R16<>"READY","",IFERROR(ROUND((ROUND(SUMIFS('Market Days'!$C$5:$C$54,'Market Days'!$A$5:$A$54,A16,'Market Days'!$B$5:$B$54,B16,'Market Days'!$I$5:$I$54,"READY"),2)+ROUND(SUMIFS('Market Days'!$D$5:$D$54,'Market Days'!$A$5:$A$54,A16,'Market Days'!$B$5:$B$54,B16,'Market Days'!$I$5:$I$54,"READY"),2))/COUNTIFS($A$5:$A$104,A16,$B$5:$B$104,B16,$R$5:$R$104,"READY"),2),"")) | L16: =IF(R16<>"READY","",IFERROR(ROUND(ROUND(G16,2)+ROUND(H16,2)+ROUND(I16*ROUND(J16,2),2)+K16,2),"")) | M16: =IF(R16<>"READY","",IFERROR(ROUND(ROUND(F16,2)-L16,2),"")) | N16: =IF(R16<>"READY","",IFERROR(IF(ROUND(F16,2)=0,"",M16/ROUND(F16,2)),"")) | O16: =IF(R16<>"READY","",IFERROR(E16/D16,"")) | P16: =IF(R16<>"READY","",IFERROR(IF(I16=0,"",M16/I16),"")) | Q16: =IF(COUNTA(A16:J16)=0,"",IF(OR(R16<>"READY",COUNTIF(Targets!$D$5:$D$7,"READY")<>3),"NEEDS REVIEW",IFERROR(IF(AND(N16<>"",P16<>"",O16<>"",ROUND(N16,3)>=ROUND(Targets!$B$5,3),ROUND(P16,2)>=ROUND(Targets!$B$6,2),ROUND(O16,3)>=ROUND(Targets!$B$7,3)),"MEETS TARGETS","REVIEW"),"REVIEW"))) | R16: =IF(COUNTA(A16:J16)=0,"",IFERROR(IF(A16="","ENTER MARKET DATE",IF(NOT(ISNUMBER(A16)),"ENTER A VALID DATE",IF(B16="","ENTER MARKET NAME",IF(C16="","ENTER PRODUCT BATCH",IF(COUNTIFS($A$5:$A$104,A16,$B$5:$B$104,B16,$C$5:$C$104,C16)>1,"REMOVE DUPLICATE PRODUCT ROW",IF(OR(NOT(ISNUMBER(D16)),D16<=0,D16<>INT(D16)),"ENTER UNITS BROUGHT AS A POSITIVE WHOLE NUMBER",IF(OR(NOT(ISNUMBER(E16)),E16<0,E16<>INT(E16),E16>D16),"CHECK WHOLE UNITS SOLD",IF(OR(NOT(ISNUMBER(F16)),F16<0),"ENTER SALES AS 0 OR MORE",IF(OR(NOT(ISNUMBER(G16)),G16<0),"ENTER INGREDIENT COST AS 0 OR MORE",IF(OR(NOT(ISNUMBER(H16)),H16<0),"ENTER PACKAGING COST AS 0 OR MORE",IF(OR(NOT(ISNUMBER(I16)),I16<0),"ENTER PRODUCT WORK HOURS AS 0 OR MORE",IF(OR(NOT(ISNUMBER(J16)),J16<0),"ENTER TIME VALUE AS 0 OR MORE",IF(COUNTIFS('Market Days'!$A$5:$A$54,A16,'Market Days'!$B$5:$B$54,B16,'Market Days'!$I$5:$I$54,"READY")<>1,"FIX OR ADD MATCHING MARKET DAY","READY"))))))))))))),"FIX INVALID PRODUCT ENTRY"))
K17: =IF(R17<>"READY","",IFERROR(ROUND((ROUND(SUMIFS('Market Days'!$C$5:$C$54,'Market Days'!$A$5:$A$54,A17,'Market Days'!$B$5:$B$54,B17,'Market Days'!$I$5:$I$54,"READY"),2)+ROUND(SUMIFS('Market Days'!$D$5:$D$54,'Market Days'!$A$5:$A$54,A17,'Market Days'!$B$5:$B$54,B17,'Market Days'!$I$5:$I$54,"READY"),2))/COUNTIFS($A$5:$A$104,A17,$B$5:$B$104,B17,$R$5:$R$104,"READY"),2),"")) | L17: =IF(R17<>"READY","",IFERROR(ROUND(ROUND(G17,2)+ROUND(H17,2)+ROUND(I17*ROUND(J17,2),2)+K17,2),"")) | M17: =IF(R17<>"READY","",IFERROR(ROUND(ROUND(F17,2)-L17,2),"")) | N17: =IF(R17<>"READY","",IFERROR(IF(ROUND(F17,2)=0,"",M17/ROUND(F17,2)),"")) | O17: =IF(R17<>"READY","",IFERROR(E17/D17,"")) | P17: =IF(R17<>"READY","",IFERROR(IF(I17=0,"",M17/I17),"")) | Q17: =IF(COUNTA(A17:J17)=0,"",IF(OR(R17<>"READY",COUNTIF(Targets!$D$5:$D$7,"READY")<>3),"NEEDS REVIEW",IFERROR(IF(AND(N17<>"",P17<>"",O17<>"",ROUND(N17,3)>=ROUND(Targets!$B$5,3),ROUND(P17,2)>=ROUND(Targets!$B$6,2),ROUND(O17,3)>=ROUND(Targets!$B$7,3)),"MEETS TARGETS","REVIEW"),"REVIEW"))) | R17: =IF(COUNTA(A17:J17)=0,"",IFERROR(IF(A17="","ENTER MARKET DATE",IF(NOT(ISNUMBER(A17)),"ENTER A VALID DATE",IF(B17="","ENTER MARKET NAME",IF(C17="","ENTER PRODUCT BATCH",IF(COUNTIFS($A$5:$A$104,A17,$B$5:$B$104,B17,$C$5:$C$104,C17)>1,"REMOVE DUPLICATE PRODUCT ROW",IF(OR(NOT(ISNUMBER(D17)),D17<=0,D17<>INT(D17)),"ENTER UNITS BROUGHT AS A POSITIVE WHOLE NUMBER",IF(OR(NOT(ISNUMBER(E17)),E17<0,E17<>INT(E17),E17>D17),"CHECK WHOLE UNITS SOLD",IF(OR(NOT(ISNUMBER(F17)),F17<0),"ENTER SALES AS 0 OR MORE",IF(OR(NOT(ISNUMBER(G17)),G17<0),"ENTER INGREDIENT COST AS 0 OR MORE",IF(OR(NOT(ISNUMBER(H17)),H17<0),"ENTER PACKAGING COST AS 0 OR MORE",IF(OR(NOT(ISNUMBER(I17)),I17<0),"ENTER PRODUCT WORK HOURS AS 0 OR MORE",IF(OR(NOT(ISNUMBER(J17)),J17<0),"ENTER TIME VALUE AS 0 OR MORE",IF(COUNTIFS('Market Days'!$A$5:$A$54,A17,'Market Days'!$B$5:$B$54,B17,'Market Days'!$I$5:$I$54,"READY")<>1,"FIX OR ADD MATCHING MARKET DAY","READY"))))))))))))),"FIX INVALID PRODUCT ENTRY"))
K18: =IF(R18<>"READY","",IFERROR(ROUND((ROUND(SUMIFS('Market Days'!$C$5:$C$54,'Market Days'!$A$5:$A$54,A18,'Market Days'!$B$5:$B$54,B18,'Market Days'!$I$5:$I$54,"READY"),2)+ROUND(SUMIFS('Market Days'!$D$5:$D$54,'Market Days'!$A$5:$A$54,A18,'Market Days'!$B$5:$B$54,B18,'Market Days'!$I$5:$I$54,"READY"),2))/COUNTIFS($A$5:$A$104,A18,$B$5:$B$104,B18,$R$5:$R$104,"READY"),2),"")) | L18: =IF(R18<>"READY","",IFERROR(ROUND(ROUND(G18,2)+ROUND(H18,2)+ROUND(I18*ROUND(J18,2),2)+K18,2),"")) | M18: =IF(R18<>"READY","",IFERROR(ROUND(ROUND(F18,2)-L18,2),"")) | N18: =IF(R18<>"READY","",IFERROR(IF(ROUND(F18,2)=0,"",M18/ROUND(F18,2)),"")) | O18: =IF(R18<>"READY","",IFERROR(E18/D18,"")) | P18: =IF(R18<>"READY","",IFERROR(IF(I18=0,"",M18/I18),"")) | Q18: =IF(COUNTA(A18:J18)=0,"",IF(OR(R18<>"READY",COUNTIF(Targets!$D$5:$D$7,"READY")<>3),"NEEDS REVIEW",IFERROR(IF(AND(N18<>"",P18<>"",O18<>"",ROUND(N18,3)>=ROUND(Targets!$B$5,3),ROUND(P18,2)>=ROUND(Targets!$B$6,2),ROUND(O18,3)>=ROUND(Targets!$B$7,3)),"MEETS TARGETS","REVIEW"),"REVIEW"))) | R18: =IF(COUNTA(A18:J18)=0,"",IFERROR(IF(A18="","ENTER MARKET DATE",IF(NOT(ISNUMBER(A18)),"ENTER A VALID DATE",IF(B18="","ENTER MARKET NAME",IF(C18="","ENTER PRODUCT BATCH",IF(COUNTIFS($A$5:$A$104,A18,$B$5:$B$104,B18,$C$5:$C$104,C18)>1,"REMOVE DUPLICATE PRODUCT ROW",IF(OR(NOT(ISNUMBER(D18)),D18<=0,D18<>INT(D18)),"ENTER UNITS BROUGHT AS A POSITIVE WHOLE NUMBER",IF(OR(NOT(ISNUMBER(E18)),E18<0,E18<>INT(E18),E18>D18),"CHECK WHOLE UNITS SOLD",IF(OR(NOT(ISNUMBER(F18)),F18<0),"ENTER SALES AS 0 OR MORE",IF(OR(NOT(ISNUMBER(G18)),G18<0),"ENTER INGREDIENT COST AS 0 OR MORE",IF(OR(NOT(ISNUMBER(H18)),H18<0),"ENTER PACKAGING COST AS 0 OR MORE",IF(OR(NOT(ISNUMBER(I18)),I18<0),"ENTER PRODUCT WORK HOURS AS 0 OR MORE",IF(OR(NOT(ISNUMBER(J18)),J18<0),"ENTER TIME VALUE AS 0 OR MORE",IF(COUNTIFS('Market Days'!$A$5:$A$54,A18,'Market Days'!$B$5:$B$54,B18,'Market Days'!$I$5:$I$54,"READY")<>1,"FIX OR ADD MATCHING MARKET DAY","READY"))))))))))))),"FIX INVALID PRODUCT ENTRY"))
K19: =IF(R19<>"READY","",IFERROR(ROUND((ROUND(SUMIFS('Market Days'!$C$5:$C$54,'Market Days'!$A$5:$A$54,A19,'Market Days'!$B$5:$B$54,B19,'Market Days'!$I$5:$I$54,"READY"),2)+ROUND(SUMIFS('Market Days'!$D$5:$D$54,'Market Days'!$A$5:$A$54,A19,'Market Days'!$B$5:$B$54,B19,'Market Days'!$I$5:$I$54,"READY"),2))/COUNTIFS($A$5:$A$104,A19,$B$5:$B$104,B19,$R$5:$R$104,"READY"),2),"")) | L19: =IF(R19<>"READY","",IFERROR(ROUND(ROUND(G19,2)+ROUND(H19,2)+ROUND(I19*ROUND(J19,2),2)+K19,2),"")) | M19: =IF(R19<>"READY","",IFERROR(ROUND(ROUND(F19,2)-L19,2),"")) | N19: =IF(R19<>"READY","",IFERROR(IF(ROUND(F19,2)=0,"",M19/ROUND(F19,2)),"")) | O19: =IF(R19<>"READY","",IFERROR(E19/D19,"")) | P19: =IF(R19<>"READY","",IFERROR(IF(I19=0,"",M19/I19),"")) | Q19: =IF(COUNTA(A19:J19)=0,"",IF(OR(R19<>"READY",COUNTIF(Targets!$D$5:$D$7,"READY")<>3),"NEEDS REVIEW",IFERROR(IF(AND(N19<>"",P19<>"",O19<>"",ROUND(N19,3)>=ROUND(Targets!$B$5,3),ROUND(P19,2)>=ROUND(Targets!$B$6,2),ROUND(O19,3)>=ROUND(Targets!$B$7,3)),"MEETS TARGETS","REVIEW"),"REVIEW"))) | R19: =IF(COUNTA(A19:J19)=0,"",IFERROR(IF(A19="","ENTER MARKET DATE",IF(NOT(ISNUMBER(A19)),"ENTER A VALID DATE",IF(B19="","ENTER MARKET NAME",IF(C19="","ENTER PRODUCT BATCH",IF(COUNTIFS($A$5:$A$104,A19,$B$5:$B$104,B19,$C$5:$C$104,C19)>1,"REMOVE DUPLICATE PRODUCT ROW",IF(OR(NOT(ISNUMBER(D19)),D19<=0,D19<>INT(D19)),"ENTER UNITS BROUGHT AS A POSITIVE WHOLE NUMBER",IF(OR(NOT(ISNUMBER(E19)),E19<0,E19<>INT(E19),E19>D19),"CHECK WHOLE UNITS SOLD",IF(OR(NOT(ISNUMBER(F19)),F19<0),"ENTER SALES AS 0 OR MORE",IF(OR(NOT(ISNUMBER(G19)),G19<0),"ENTER INGREDIENT COST AS 0 OR MORE",IF(OR(NOT(ISNUMBER(H19)),H19<0),"ENTER PACKAGING COST AS 0 OR MORE",IF(OR(NOT(ISNUMBER(I19)),I19<0),"ENTER PRODUCT WORK HOURS AS 0 OR MORE",IF(OR(NOT(ISNUMBER(J19)),J19<0),"ENTER TIME VALUE AS 0 OR MORE",IF(COUNTIFS('Market Days'!$A$5:$A$54,A19,'Market Days'!$B$5:$B$54,B19,'Market Days'!$I$5:$I$54,"READY")<>1,"FIX OR ADD MATCHING MARKET DAY","READY"))))))))))))),"FIX INVALID PRODUCT ENTRY"))
K20: =IF(R20<>"READY","",IFERROR(ROUND((ROUND(SUMIFS('Market Days'!$C$5:$C$54,'Market Days'!$A$5:$A$54,A20,'Market Days'!$B$5:$B$54,B20,'Market Days'!$I$5:$I$54,"READY"),2)+ROUND(SUMIFS('Market Days'!$D$5:$D$54,'Market Days'!$A$5:$A$54,A20,'Market Days'!$B$5:$B$54,B20,'Market Days'!$I$5:$I$54,"READY"),2))/COUNTIFS($A$5:$A$104,A20,$B$5:$B$104,B20,$R$5:$R$104,"READY"),2),"")) | L20: =IF(R20<>"READY","",IFERROR(ROUND(ROUND(G20,2)+ROUND(H20,2)+ROUND(I20*ROUND(J20,2),2)+K20,2),"")) | M20: =IF(R20<>"READY","",IFERROR(ROUND(ROUND(F20,2)-L20,2),"")) | N20: =IF(R20<>"READY","",IFERROR(IF(ROUND(F20,2)=0,"",M20/ROUND(F20,2)),"")) | O20: =IF(R20<>"READY","",IFERROR(E20/D20,"")) | P20: =IF(R20<>"READY","",IFERROR(IF(I20=0,"",M20/I20),"")) | Q20: =IF(COUNTA(A20:J20)=0,"",IF(OR(R20<>"READY",COUNTIF(Targets!$D$5:$D$7,"READY")<>3),"NEEDS REVIEW",IFERROR(IF(AND(N20<>"",P20<>"",O20<>"",ROUND(N20,3)>=ROUND(Targets!$B$5,3),ROUND(P20,2)>=ROUND(Targets!$B$6,2),ROUND(O20,3)>=ROUND(Targets!$B$7,3)),"MEETS TARGETS","REVIEW"),"REVIEW"))) | R20: =IF(COUNTA(A20:J20)=0,"",IFERROR(IF(A20="","ENTER MARKET DATE",IF(NOT(ISNUMBER(A20)),"ENTER A VALID DATE",IF(B20="","ENTER MARKET NAME",IF(C20="","ENTER PRODUCT BATCH",IF(COUNTIFS($A$5:$A$104,A20,$B$5:$B$104,B20,$C$5:$C$104,C20)>1,"REMOVE DUPLICATE PRODUCT ROW",IF(OR(NOT(ISNUMBER(D20)),D20<=0,D20<>INT(D20)),"ENTER UNITS BROUGHT AS A POSITIVE WHOLE NUMBER",IF(OR(NOT(ISNUMBER(E20)),E20<0,E20<>INT(E20),E20>D20),"CHECK WHOLE UNITS SOLD",IF(OR(NOT(ISNUMBER(F20)),F20<0),"ENTER SALES AS 0 OR MORE",IF(OR(NOT(ISNUMBER(G20)),G20<0),"ENTER INGREDIENT COST AS 0 OR MORE",IF(OR(NOT(ISNUMBER(H20)),H20<0),"ENTER PACKAGING COST AS 0 OR MORE",IF(OR(NOT(ISNUMBER(I20)),I20<0),"ENTER PRODUCT WORK HOURS AS 0 OR MORE",IF(OR(NOT(ISNUMBER(J20)),J20<0),"ENTER TIME VALUE AS 0 OR MORE",IF(COUNTIFS('Market Days'!$A$5:$A$54,A20,'Market Days'!$B$5:$B$54,B20,'Market Days'!$I$5:$I$54,"READY")<>1,"FIX OR ADD MATCHING MARKET DAY","READY"))))))))))))),"FIX INVALID PRODUCT ENTRY"))
K21: =IF(R21<>"READY","",IFERROR(ROUND((ROUND(SUMIFS('Market Days'!$C$5:$C$54,'Market Days'!$A$5:$A$54,A21,'Market Days'!$B$5:$B$54,B21,'Market Days'!$I$5:$I$54,"READY"),2)+ROUND(SUMIFS('Market Days'!$D$5:$D$54,'Market Days'!$A$5:$A$54,A21,'Market Days'!$B$5:$B$54,B21,'Market Days'!$I$5:$I$54,"READY"),2))/COUNTIFS($A$5:$A$104,A21,$B$5:$B$104,B21,$R$5:$R$104,"READY"),2),"")) | L21: =IF(R21<>"READY","",IFERROR(ROUND(ROUND(G21,2)+ROUND(H21,2)+ROUND(I21*ROUND(J21,2),2)+K21,2),"")) | M21: =IF(R21<>"READY","",IFERROR(ROUND(ROUND(F21,2)-L21,2),"")) | N21: =IF(R21<>"READY","",IFERROR(IF(ROUND(F21,2)=0,"",M21/ROUND(F21,2)),"")) | O21: =IF(R21<>"READY","",IFERROR(E21/D21,"")) | P21: =IF(R21<>"READY","",IFERROR(IF(I21=0,"",M21/I21),"")) | Q21: =IF(COUNTA(A21:J21)=0,"",IF(OR(R21<>"READY",COUNTIF(Targets!$D$5:$D$7,"READY")<>3),"NEEDS REVIEW",IFERROR(IF(AND(N21<>"",P21<>"",O21<>"",ROUND(N21,3)>=ROUND(Targets!$B$5,3),ROUND(P21,2)>=ROUND(Targets!$B$6,2),ROUND(O21,3)>=ROUND(Targets!$B$7,3)),"MEETS TARGETS","REVIEW"),"REVIEW"))) | R21: =IF(COUNTA(A21:J21)=0,"",IFERROR(IF(A21="","ENTER MARKET DATE",IF(NOT(ISNUMBER(A21)),"ENTER A VALID DATE",IF(B21="","ENTER MARKET NAME",IF(C21="","ENTER PRODUCT BATCH",IF(COUNTIFS($A$5:$A$104,A21,$B$5:$B$104,B21,$C$5:$C$104,C21)>1,"REMOVE DUPLICATE PRODUCT ROW",IF(OR(NOT(ISNUMBER(D21)),D21<=0,D21<>INT(D21)),"ENTER UNITS BROUGHT AS A POSITIVE WHOLE NUMBER",IF(OR(NOT(ISNUMBER(E21)),E21<0,E21<>INT(E21),E21>D21),"CHECK WHOLE UNITS SOLD",IF(OR(NOT(ISNUMBER(F21)),F21<0),"ENTER SALES AS 0 OR MORE",IF(OR(NOT(ISNUMBER(G21)),G21<0),"ENTER INGREDIENT COST AS 0 OR MORE",IF(OR(NOT(ISNUMBER(H21)),H21<0),"ENTER PACKAGING COST AS 0 OR MORE",IF(OR(NOT(ISNUMBER(I21)),I21<0),"ENTER PRODUCT WORK HOURS AS 0 OR MORE",IF(OR(NOT(ISNUMBER(J21)),J21<0),"ENTER TIME VALUE AS 0 OR MORE",IF(COUNTIFS('Market Days'!$A$5:$A$54,A21,'Market Days'!$B$5:$B$54,B21,'Market Days'!$I$5:$I$54,"READY")<>1,"FIX OR ADD MATCHING MARKET DAY","READY"))))))))))))),"FIX INVALID PRODUCT ENTRY"))
K22: =IF(R22<>"READY","",IFERROR(ROUND((ROUND(SUMIFS('Market Days'!$C$5:$C$54,'Market Days'!$A$5:$A$54,A22,'Market Days'!$B$5:$B$54,B22,'Market Days'!$I$5:$I$54,"READY"),2)+ROUND(SUMIFS('Market Days'!$D$5:$D$54,'Market Days'!$A$5:$A$54,A22,'Market Days'!$B$5:$B$54,B22,'Market Days'!$I$5:$I$54,"READY"),2))/COUNTIFS($A$5:$A$104,A22,$B$5:$B$104,B22,$R$5:$R$104,"READY"),2),"")) | L22: =IF(R22<>"READY","",IFERROR(ROUND(ROUND(G22,2)+ROUND(H22,2)+ROUND(I22*ROUND(J22,2),2)+K22,2),"")) | M22: =IF(R22<>"READY","",IFERROR(ROUND(ROUND(F22,2)-L22,2),"")) | N22: =IF(R22<>"READY","",IFERROR(IF(ROUND(F22,2)=0,"",M22/ROUND(F22,2)),"")) | O22: =IF(R22<>"READY","",IFERROR(E22/D22,"")) | P22: =IF(R22<>"READY","",IFERROR(IF(I22=0,"",M22/I22),"")) | Q22: =IF(COUNTA(A22:J22)=0,"",IF(OR(R22<>"READY",COUNTIF(Targets!$D$5:$D$7,"READY")<>3),"NEEDS REVIEW",IFERROR(IF(AND(N22<>"",P22<>"",O22<>"",ROUND(N22,3)>=ROUND(Targets!$B$5,3),ROUND(P22,2)>=ROUND(Targets!$B$6,2),ROUND(O22,3)>=ROUND(Targets!$B$7,3)),"MEETS TARGETS","REVIEW"),"REVIEW"))) | R22: =IF(COUNTA(A22:J22)=0,"",IFERROR(IF(A22="","ENTER MARKET DATE",IF(NOT(ISNUMBER(A22)),"ENTER A VALID DATE",IF(B22="","ENTER MARKET NAME",IF(C22="","ENTER PRODUCT BATCH",IF(COUNTIFS($A$5:$A$104,A22,$B$5:$B$104,B22,$C$5:$C$104,C22)>1,"REMOVE DUPLICATE PRODUCT ROW",IF(OR(NOT(ISNUMBER(D22)),D22<=0,D22<>INT(D22)),"ENTER UNITS BROUGHT AS A POSITIVE WHOLE NUMBER",IF(OR(NOT(ISNUMBER(E22)),E22<0,E22<>INT(E22),E22>D22),"CHECK WHOLE UNITS SOLD",IF(OR(NOT(ISNUMBER(F22)),F22<0),"ENTER SALES AS 0 OR MORE",IF(OR(NOT(ISNUMBER(G22)),G22<0),"ENTER INGREDIENT COST AS 0 OR MORE",IF(OR(NOT(ISNUMBER(H22)),H22<0),"ENTER PACKAGING COST AS 0 OR MORE",IF(OR(NOT(ISNUMBER(I22)),I22<0),"ENTER PRODUCT WORK HOURS AS 0 OR MORE",IF(OR(NOT(ISNUMBER(J22)),J22<0),"ENTER TIME VALUE AS 0 OR MORE",IF(COUNTIFS('Market Days'!$A$5:$A$54,A22,'Market Days'!$B$5:$B$54,B22,'Market Days'!$I$5:$I$54,"READY")<>1,"FIX OR ADD MATCHING MARKET DAY","READY"))))))))))))),"FIX INVALID PRODUCT ENTRY"))
... K104: =IF(R104<>"READY","",IFERROR(ROUND((ROUND(SUMIFS('Market Days'!$C$5:$C$54,'Market Days'!$A$5:$A$54,A104,'Market Days'!$B$5:$B$54,B104,'Market Days'!$I$5:$I$54,"READY"),2)+ROUND(SUMIFS('Market Days'!$D$5:$D$54,'Market Days'!$A$5:$A$54,A104,'Market Days'!$B$5:$B$54,B104,'Market Days'!$I$5:$I$54,"READY"),2))/COUNTIFS($A$5:$A$104,A104,$B$5:$B$104,B104,$R$5:$R$104,"READY"),2),"")) | L104: =IF(R104<>"READY","",IFERROR(ROUND(ROUND(G104,2)+ROUND(H104,2)+ROUND(I104*ROUND(J104,2),2)+K104,2),"")) | M104: =IF(R104<>"READY","",IFERROR(ROUND(ROUND(F104,2)-L104,2),"")) | N104: =IF(R104<>"READY","",IFERROR(IF(ROUND(F104,2)=0,"",M104/ROUND(F104,2)),"")) | O104: =IF(R104<>"READY","",IFERROR(E104/D104,"")) | P104: =IF(R104<>"READY","",IFERROR(IF(I104=0,"",M104/I104),"")) | Q104: =IF(COUNTA(A104:J104)=0,"",IF(OR(R104<>"READY",COUNTIF(Targets!$D$5:$D$7,"READY")<>3),"NEEDS REVIEW",IFERROR(IF(AND(N104<>"",P104<>"",O104<>"",ROUND(N104,3)>=ROUND(Targets!$B$5,3),ROUND(P104,2)>=ROUND(Targets!$B$6,2),ROUND(O104,3)>=ROUND(Targets!$B$7,3)),"MEETS TARGETS","REVIEW"),"REVIEW"))) | R104: =IF(COUNTA(A104:J104)=0,"",IFERROR(IF(A104="","ENTER MARKET DATE",IF(NOT(ISNUMBER(A104)),"ENTER A VALID DATE",IF(B104="","ENTER MARKET NAME",IF(C104="","ENTER PRODUCT BATCH",IF(COUNTIFS($A$5:$A$104,A104,$B$5:$B$104,B104,$C$5:$C$104,C104)>1,"REMOVE DUPLICATE PRODUCT ROW",IF(OR(NOT(ISNUMBER(D104)),D104<=0,D104<>INT(D104)),"ENTER UNITS BROUGHT AS A POSITIVE WHOLE NUMBER",IF(OR(NOT(ISNUMBER(E104)),E104<0,E104<>INT(E104),E104>D104),"CHECK WHOLE UNITS SOLD",IF(OR(NOT(ISNUMBER(F104)),F104<0),"ENTER SALES AS 0 OR MORE",IF(OR(NOT(ISNUMBER(G104)),G104<0),"ENTER INGREDIENT COST AS 0 OR MORE",IF(OR(NOT(ISNUMBER(H104)),H104<0),"ENTER PACKAGING COST AS 0 OR MORE",IF(OR(NOT(ISNUMBER(I104)),I104<0),"ENTER PRODUCT WORK HOURS AS 0 OR MORE",IF(OR(NOT(ISNUMBER(J104)),J104<0),"ENTER TIME VALUE AS 0 OR MORE",IF(COUNTIFS('Market Days'!$A$5:$A$54,A104,'Market Days'!$B$5:$B$54,B104,'Market Days'!$I$5:$I$54,"READY")<>1,"FIX OR ADD MATCHING MARKET DAY","READY"))))))))))))),"FIX INVALID PRODUCT ENTRY"))

Sheet Market Comparison
A1: Market Comparison
A2: Enter up to five market names exactly as they appear on Market Days. Results combine READY rows for each market.
A3: SAMPLE DATA — the market names below are examples. Replace them with your own market names.
A4: Market Name | B4: Sales | C4: Profit After Entered Costs | D4: Profit Margin | E4: Units Sold | F4: Stock Sold % | G4: Profit per Market Hour | H4: Target Check | I4: Input Check / What to Fix
A5: Saturday Market | B5: =IF($A5="","",SUMIFS('Product Sales'!$L$5:$L$104,'Product Sales'!$B$5:$B$104,$A5,'Product Sales'!$R$5:$R$104,"READY")+SUMIFS('Product Sales'!$M$5:$M$104,'Product Sales'!$B$5:$B$104,$A5,'Product Sales'!$R$5:$R$104,"READY")) -> 487 | C5: =IF($A5="","",SUMIFS('Product Sales'!$M$5:$M$104,'Product Sales'!$B$5:$B$104,$A5,'Product Sales'!$R$5:$R$104,"READY")) -> 109 | D5: =IFERROR(C5/B5,"") -> 0.2238193 | E5: =IF($A5="","",SUMIFS('Product Sales'!$E$5:$E$104,'Product Sales'!$B$5:$B$104,$A5,'Product Sales'!$R$5:$R$104,"READY")) -> 46 | F5: =IFERROR(E5/SUMIFS('Product Sales'!$D$5:$D$104,'Product Sales'!$B$5:$B$104,$A5,'Product Sales'!$R$5:$R$104,"READY"),"") -> 0.76666667 | G5: =IFERROR(C5/SUMIFS('Market Days'!$E$5:$E$54,'Market Days'!$B$5:$B$54,$A5,'Market Days'!$I$5:$I$54,"READY"),"") -> 15.571429 | H5: =IF(A5="","",IF(OR(I5<>"READY",COUNTIF(Targets!$D$5:$D$7,"READY")<>3),"NEEDS REVIEW",IF(AND(D5<>"",F5<>"",G5<>"",ROUND(D5,3)>=ROUND(Targets!$B$5,3),ROUND(G5,2)>=ROUND(Targets!$B$6,2),ROUND(F5,3)>=ROUND(Targets!$B$7,3)),"MEETS TARGETS","REVIEW"))) -> REVIEW | I5: =IF(A5="","",IFERROR(IF(COUNTIF('Market Days'!$B$5:$B$54,A5)=0,"MARKET NOT FOUND",IF(COUNTIF('Market Days'!$B$5:$B$54,A5)<>COUNTIFS('Market Days'!$B$5:$B$54,A5,'Market Days'!$I$5:$I$54,"READY"),"FIX MARKET DAY",IF(COUNTIFS('Product Sales'!$B$5:$B$104,A5,'Product Sales'!$R$5:$R$104,"READY")=0,"ADD READY PRODUCT SALES","READY"))),"FIX THIS MARKET")) -> READY
A6: Riverside Pop-Up | B6: =IF($A6="","",SUMIFS('Product Sales'!$L$5:$L$104,'Product Sales'!$B$5:$B$104,$A6,'Product Sales'!$R$5:$R$104,"READY")+SUMIFS('Product Sales'!$M$5:$M$104,'Product Sales'!$B$5:$B$104,$A6,'Product Sales'!$R$5:$R$104,"READY")) -> 478 | C6: =IF($A6="","",SUMIFS('Product Sales'!$M$5:$M$104,'Product Sales'!$B$5:$B$104,$A6,'Product Sales'!$R$5:$R$104,"READY")) -> 182 | D6: =IFERROR(C6/B6,"") -> 0.38075314 | E6: =IF($A6="","",SUMIFS('Product Sales'!$E$5:$E$104,'Product Sales'!$B$5:$B$104,$A6,'Product Sales'!$R$5:$R$104,"READY")) -> 44 | F6: =IFERROR(E6/SUMIFS('Product Sales'!$D$5:$D$104,'Product Sales'!$B$5:$B$104,$A6,'Product Sales'!$R$5:$R$104,"READY"),"") -> 0.88 | G6: =IFERROR(C6/SUMIFS('Market Days'!$E$5:$E$54,'Market Days'!$B$5:$B$54,$A6,'Market Days'!$I$5:$I$54,"READY"),"") -> 36.4 | H6: =IF(A6="","",IF(OR(I6<>"READY",COUNTIF(Targets!$D$5:$D$7,"READY")<>3),"NEEDS REVIEW",IF(AND(D6<>"",F6<>"",G6<>"",ROUND(D6,3)>=ROUND(Targets!$B$5,3),ROUND(G6,2)>=ROUND(Targets!$B$6,2),ROUND(F6,3)>=ROUND(Targets!$B$7,3)),"MEETS TARGETS","REVIEW"))) -> MEETS TARGETS | I6: =IF(A6="","",IFERROR(IF(COUNTIF('Market Days'!$B$5:$B$54,A6)=0,"MARKET NOT FOUND",IF(COUNTIF('Market Days'!$B$5:$B$54,A6)<>COUNTIFS('Market Days'!$B$5:$B$54,A6,'Market Days'!$I$5:$I$54,"READY"),"FIX MARKET DAY",IF(COUNTIFS('Product Sales'!$B$5:$B$104,A6,'Product Sales'!$R$5:$R$104,"READY")=0,"ADD READY PRODUCT SALES","READY"))),"FIX THIS MARKET")) -> READY
A7: Night Bazaar | B7: =IF($A7="","",SUMIFS('Product Sales'!$L$5:$L$104,'Product Sales'!$B$5:$B$104,$A7,'Product Sales'!$R$5:$R$104,"READY")+SUMIFS('Product Sales'!$M$5:$M$104,'Product Sales'!$B$5:$B$104,$A7,'Product Sales'!$R$5:$R$104,"READY")) -> 509 | C7: =IF($A7="","",SUMIFS('Product Sales'!$M$5:$M$104,'Product Sales'!$B$5:$B$104,$A7,'Product Sales'!$R$5:$R$104,"READY")) -> 51 | D7: =IFERROR(C7/B7,"") -> 0.10019646 | E7: =IF($A7="","",SUMIFS('Product Sales'!$E$5:$E$104,'Product Sales'!$B$5:$B$104,$A7,'Product Sales'!$R$5:$R$104,"READY")) -> 47 | F7: =IFERROR(E7/SUMIFS('Product Sales'!$D$5:$D$104,'Product Sales'!$B$5:$B$104,$A7,'Product Sales'!$R$5:$R$104,"READY"),"") -> 0.67142857 | G7: =IFERROR(C7/SUMIFS('Market Days'!$E$5:$E$54,'Market Days'!$B$5:$B$54,$A7,'Market Days'!$I$5:$I$54,"READY"),"") -> 6.375 | H7: =IF(A7="","",IF(OR(I7<>"READY",COUNTIF(Targets!$D$5:$D$7,"READY")<>3),"NEEDS REVIEW",IF(AND(D7<>"",F7<>"",G7<>"",ROUND(D7,3)>=ROUND(Targets!$B$5,3),ROUND(G7,2)>=ROUND(Targets!$B$6,2),ROUND(F7,3)>=ROUND(Targets!$B$7,3)),"MEETS TARGETS","REVIEW"))) -> REVIEW | I7: =IF(A7="","",IFERROR(IF(COUNTIF('Market Days'!$B$5:$B$54,A7)=0,"MARKET NOT FOUND",IF(COUNTIF('Market Days'!$B$5:$B$54,A7)<>COUNTIFS('Market Days'!$B$5:$B$54,A7,'Market Days'!$I$5:$I$54,"READY"),"FIX MARKET DAY",IF(COUNTIFS('Product Sales'!$B$5:$B$104,A7,'Product Sales'!$R$5:$R$104,"READY")=0,"ADD READY PRODUCT SALES","READY"))),"FIX THIS MARKET")) -> READY
B8: =IF($A8="","",SUMIFS('Product Sales'!$L$5:$L$104,'Product Sales'!$B$5:$B$104,$A8,'Product Sales'!$R$5:$R$104,"READY")+SUMIFS('Product Sales'!$M$5:$M$104,'Product Sales'!$B$5:$B$104,$A8,'Product Sales'!$R$5:$R$104,"READY")) | C8: =IF($A8="","",SUMIFS('Product Sales'!$M$5:$M$104,'Product Sales'!$B$5:$B$104,$A8,'Product Sales'!$R$5:$R$104,"READY")) | D8: =IFERROR(C8/B8,"") | E8: =IF($A8="","",SUMIFS('Product Sales'!$E$5:$E$104,'Product Sales'!$B$5:$B$104,$A8,'Product Sales'!$R$5:$R$104,"READY")) | F8: =IFERROR(E8/SUMIFS('Product Sales'!$D$5:$D$104,'Product Sales'!$B$5:$B$104,$A8,'Product Sales'!$R$5:$R$104,"READY"),"") | G8: =IFERROR(C8/SUMIFS('Market Days'!$E$5:$E$54,'Market Days'!$B$5:$B$54,$A8,'Market Days'!$I$5:$I$54,"READY"),"") | H8: =IF(A8="","",IF(OR(I8<>"READY",COUNTIF(Targets!$D$5:$D$7,"READY")<>3),"NEEDS REVIEW",IF(AND(D8<>"",F8<>"",G8<>"",ROUND(D8,3)>=ROUND(Targets!$B$5,3),ROUND(G8,2)>=ROUND(Targets!$B$6,2),ROUND(F8,3)>=ROUND(Targets!$B$7,3)),"MEETS TARGETS","REVIEW"))) | I8: =IF(A8="","",IFERROR(IF(COUNTIF('Market Days'!$B$5:$B$54,A8)=0,"MARKET NOT FOUND",IF(COUNTIF('Market Days'!$B$5:$B$54,A8)<>COUNTIFS('Market Days'!$B$5:$B$54,A8,'Market Days'!$I$5:$I$54,"READY"),"FIX MARKET DAY",IF(COUNTIFS('Product Sales'!$B$5:$B$104,A8,'Product Sales'!$R$5:$R$104,"READY")=0,"ADD READY PRODUCT SALES","READY"))),"FIX THIS MARKET"))
